Workbook

Sheet REGION 1 SAN JOSÉ CENTRAL
A1: REGION | B1: DELEGACION POLICIAL | C1: ACTIVIDAD 1 CHARLA PREVENCIÓN DE LA VIOLENCIA EN RELACIONES DE PAREJA EJE 1 PLANOVI (JOVENES ADOLESCENTES) EJECUTAR MES DE MAYO LÍNEA BASE 100 PERSONAS | G1: ACTIVIDAD 2 CHARLA PREVENCIÓN DE LA VIOLENCIA DOMÉSTICA E INTRAFAMILIAR EJE 1 PLANOVI (PERSONAS ADULTAS) EJECUTAR MES DE AGOSTO LINEA BASE 25 PERSONAS | K1: ACTIVIDAD 3 CHARLA PREVENCIÓN DE LA MASCULINIDAD POR LA IGUALDAD EJE 2 PLANOVI (JOVENES Y ADOLESCENTES) EJECUTAR MES DE MAYO LÍNEA BASE 75 PERSONAS | O1: ACTIVIDAD 4 CHARLA PREVENCIÓN DE LA MASCULINIDAD POR LA IGUALDAD ADULTOS EJE 2 PLANOVI (COMUNIDAD) EJECUTAR MES DE AGOSTO LÍNEA BASE 15 PERSONAS | S1: ACTIVIDAD 5 CHARLA TRATA DE PERSONAS JOVENES ADOLESCENTES EJE 1 CONATT EJECUTAR MES DE MAYO LÍNEA BASE 50 PERSONAS | W1: ACTIVIDAD 6 CHARLA TRATA DE PERSONAS ADULTOS COMUNIDADES EJE 1 CONATT EJECUTAR MES DE AGOSTO LÍNEA BASE 10 PARTICIPANTES | AA1: ACTIVIDAD 7 CHARLA PREVENCIÓN DEL FEMICIDIO Y DIVULGACION COMITES CLAIS PERSONAS ADULTAS EJE 6 PLANOVI EJECUTAR MES DE OCTUBRE LÍNEA BASE 15 | AE1: ACTIVIDAD 8 ESTRATEGIA DE COMUNICACIÓN EJE 1 PLANOVI PREVENCION DE LA VIOLENCIA CONTRA LAS MUJERES EJECUTAR MES DE MARZO LÍNEA BASE 100 PERSONAS | AI1: ACTIVIDAD 9 ESTRATEGIA DE COMUNICACIÓN EJE 2 PLANOVI MASCULINIDAD POR LA IGUALDAD EJECUTAR MES DE JUNIO LÍNEA BASE 100 PERSONAS | AM1: ACTIVIDAD 10 ESTRATEGIA DE COMUNICACIÓN EJE 5 PLANOVI PREVENCIÓN, ATENCIÓN INTEGRAL Y NO-REVICTIMIZACIÓN FRENTE A LA VIOLENCIA SEXUAL EJECUTAR MES DE SETIEMBRE LÍNEA BASE 100 PERSONAS | AQ1: ACTIVIDAD 11 ESTRATEGIA DE COMUNICACIÓN EJE 6 PLANOVI PREVENCIÓN DEL FEMICIDIO EJECUTAR MES DE NOVIEMBRE LÍNEA BASE 100 PERSONAS | AU1: ACTIVIDAD 12 ESTRATEGIA DE COMUNICACIÓN EJE 1 CONATT CONTRA LA TRATA DE PERSONAS EJECUTAR MES DE JULIO LÍNEA BASE 100 PERSONAS | AY1: ACTIVIDAD 13 ESTRATEGIA DE COMUNICACIÓN EJE 1 CONATT TRAFICO ILICITO PERSONAS MIGRANTES EJECUTAR MES DE DICIEMBRE LÍNEA BASE 100 PERSONAS | BC1: ACTIVIDAD 14 ESTRATEGIA DE COMUNICACIÓN JUSTICIA RESTAURATIVA EJECUTAR MES DE ABRIL 50% COMITÉS SEGURIDAD COMUNITARIA | BG1: ACTIVIDAD 15 ESTRATEGIA DE COMUNICACIÓN JUSTICIA RESTAURATIVA EJECUTAR MES DE ABRIL 50% COMERCIOS | BK1: ACTIVIDAD 16 REPRESENTACION INSTITUCIONAL REDES CONTRA LA VIOLENCIA INTRAFAMILIAR PLANOVI CANTIDAD DE PARTICIPACIÓN POR TRIMESTRE | BO1: ACTIVIDAD 17 REPRESENTACION INSTITUCIONAL SUBSISTEMA LOCAL NIÑEZ Y ADOLESCENCIA (PANI) CANTIDAD DE PARTICIPACIÓN POR TRIMESTRE | BS1: ACTIVIDAD 18 REPRESENTACION INSTITUCIONAL COMITÉ LOCAL CLAIS (PODER JUDICIAL-INAMU-FUERZA PUBLICA) CANTIDAD DE PARTICIPACIÓN POR TRIMESTRE
C2: PRIMER TRIMESTRE | D2: SEGUNDO TRIMESTRE | E2: TERCER TRIMESTRE | F2: CUARTO TRIMESTRE | G2: PRIMER TRIMESTRE | H2: SEGUNDO TRIMESTRE | I2: TERCER TRIMESTRE | J2: CUARTO TRIMESTRE | K2: PRIMER TRIMESTRE | L2: SEGUNDO TRIMESTRE | M2: TERCER TRIMESTRE | N2: CUARTO TRIMESTRE | O2: PRIMER TRIMESTRE | P2: SEGUNDO TRIMESTRE | Q2: TERCER TRIMESTRE | R2: CUARTO TRIMESTRE | S2: PRIMER TRIMESTRE | T2: SEGUNDO TRIMESTRE | U2: TERCER TRIMESTRE | V2: CUARTO TRIMESTRE | W2: PRIMER TRIMESTRE | X2: SEGUNDO TRIMESTRE | Y2: TERCER TRIMESTRE | Z2: CUARTO TRIMESTRE | AA2: PRIMER TRIMESTRE | AB2: SEGUNDO TRIMESTRE | AC2: TERCER TRIMESTRE | AD2: CUARTO TRIMESTRE | AE2: PRIMER TRIMESTRE | AF2: SEGUNDO TRIMESTRE | AG2: TERCER TRIMESTRE | AH2: CUARTO TRIMESTRE | AI2: PRIMER TRIMESTRE | AJ2: SEGUNDO TRIMESTRE | AK2: TERCER TRIMESTRE | AL2: CUARTO TRIMESTRE | AM2: PRIMER TRIMESTRE | AN2: SEGUNDO TRIMESTRE | AO2: TERCER TRIMESTRE | AP2: CUARTO TRIMESTRE | AQ2: PRIMER TRIMESTRE | AR2: SEGUNDO TRIMESTRE | AS2: TERCER TRIMESTRE | AT2: CUARTO TRIMESTRE | AU2: PRIMER TRIMESTRE | AV2: SEGUNDO TRIMESTRE | AW2: TERCER TRIMESTRE | AX2: CUARTO TRIMESTRE | AY2: PRIMER TRIMESTRE | AZ2: SEGUNDO TRIMESTRE | BA2: TERCER TRIMESTRE | BB2: CUARTO TRIMESTRE | BC2: PRIMER TRIMESTRE | BD2: SEGUNDO TRIMESTRE | BE2: TERCER TRIMESTRE | BF2: CUARTO TRIMESTRE | BG2: PRIMER TRIMESTRE | BH2: SEGUNDO TRIMESTRE | BI2: TERCER TRIMESTRE | BJ2: CUARTO TRIMESTRE | BK2: PRIMER TRIMESTRE | BL2: SEGUNDO TRIMESTRE | BM2: TERCER TRIMESTRE | BN2: CUARTO TRIMESTRE | BO2: PRIMER TRIMESTRE | BP2: SEGUNDO TRIMESTRE | BQ2: TERCER TRIMESTRE | BR2: CUARTO TRIMESTRE | BS2: PRIMER TRIMESTRE | BT2: SEGUNDO TRIMESTRE | BU2: TERCER TRIMESTRE | BV2: CUARTO TRIMESTRE
A3: PRIMERA SAN JOSE CENTRAL | B3: METROPOLITANA
B4: D-1 CARMEN | D4: 140 | L4: 140 | T4: 60 | AE4: 120 | BD4: 1 | BH4: 1 | BL4: 3 | BP4: 1 | BS4: 2 | BT4: 2
B5: D-2 MERCED | D5: 125 | L5: 100 | T5: 60 | AE5: 100 | BD5: 1 | BH5: 1 | BL5: 2 | BO5: 1 | BP5: 1 | BS5: 2
B6: D-3 HOSPITAL | D6: 143 | L6: 129 | T6: 50 | AE6: 119 | AJ6: 123 | BD6: 1 | BH6: 1 | BK6: 3 | BL6: 3 | BO6: 1 | BP6: 2 | BS6: 1 | BT6: 3
B7: D-4 CATEDRAL | D7: 125 | L7: 135 | T7: 80 | AB7: 1 | AE7: 400 | AJ7: 100 | BD7: 1 | BH7: 1 | BL7: 2 | BO7: 1 | BP7: 1 | BS7: 2 | BT7: 1
B8: D-5 SAN SEBASTIAN | D8: 125 | L8: 0 | T8: 50 | AB8: 1 | AE8: 100 | BD8: 1 | BH8: 1 | BK8: 2 | BL8: 2 | BO8: 2 | BP8: 1 | BT8: 1
B9: D-6 HATILLO | D9: 357 | L9: 357 | T9: 357 | AB9: 1 | AE9: 176 | AJ9: 171 | BD9: 1 | BH9: 1 | BL9: 1 | BO9: 2 | BP9: 1 | BT9: 1
B10: D-7 ZAPOTE/SAN FRANCISCO | D10: 140 | L10: 156 | T10: 199 | AB10: 2 | AE10: 100 | BD10: 1 | BH10: 1 | BL10: 3 | BO10: 1 | BP10: 3 | BS10: 3 | BT10: 0
B11: D-8 PAVAS | D11: 125 | L11: 100 | T11: 50 | AE11: 100 | BD11: 1 | BH11: 1 | BK11: 1 | BL11: 3
B12: D-9 URUCA/MATA REDONDA | D12: 134 | L12: 120 | T12: 100 | AE12: 100 | BD12: 1 | BH12: 1 | BL12: 3 | BP12: 2 | BS12: 2 | BT12: 1 | BV12: 1
C13: =SUM(C4:C12) -> 0 | D13: =SUM(D4:D12) -> 1414 | E13: =SUM(E4:E12) -> 0 | F13: =SUM(F4:F12) -> 0 | G13: =SUM(G4:G12) -> 0 | H13: =SUM(H4:H12) -> 0 | I13: =SUM(I4:I12) -> 0 | J13: =SUM(J4:J12) -> 0 | ... BB13: =SUM(BB4:BB12) -> 0 | BD13: 1 | BH13: 1 | BI13: =SUM(BI4:BI12) -> 0 | BJ13: =SUM(BJ4:BJ12) -> 0 | BK13: =SUM(BK4:BK12) -> 6 | BL13: =SUM(BL4:BL12) -> 22 | BM13: =SUM(BM4:BM12) -> 0 | BN13: =SUM(BN4:BN12) -> 0 | BO13: =SUM(BO4:BO12) -> 8 | BP13: =SUM(BP4:BP12) -> 12 | ... BV13: =SUM(BV4:BV12) -> 1
B14: TOTAL | C14: =SUM(C13+D13+E13+F13) -> 1414 | G14: =SUM(G13+H13+I13+J13) -> 0 | K14: =SUM(K13+L13+M13+N13) -> 1237 | O14: =SUM(O13+P13+Q13+R13) -> 0 | S14: =SUM(S13+T13+U13+V13) -> 1006 | W14: =SUM(W13+X13+Y13+Z13) -> 0 | AA14: =SUM(AA13+AB13+AC13+AD13) -> 5 | AE14: =SUM(AE13:AH13) -> 1315 | AI14: =SUM(AI13+AJ13+AK13+AL13) -> 394 | AM14: =SUM(AM13+AN13+AO13+AP13) -> 0 | AQ14: =SUM(AQ13+AR13+AS13+AT13) -> 0 | AU14: =SUM(AU13:AX13) -> 0 | AY14: =SUM(AY13:BB13) -> 0 | BC14: 1 | BG14: 1 | BK14: =SUM(BK13:BN13) -> 28 | BO14: =SUM(BO13:BR13) -> 20 | BS14: =SUM(BS13:BV13) -> 22

Sheet REGIÓN 1 SAN JOSÉ NORTE
A1: REGION | B1: DELEGACION POLICIAL | C1: ACTIVIDAD 1 CHARLA PREVENCIÓN DE LA VIOLENCIA EN RELACIONES DE PAREJA EJE 1 PLANOVI (JOVENES ADOLESCENTES) EJECUTAR MES DE MAYO LÍNEA BASE 125 PERSONAS | G1: ACTIVIDAD 2 CHARLA PREVENCIÓN DE LA VIOLENCIA DOMÉSTICA E INTRAFAMILIAR EJE 1 PLANOVI (PERSONAS ADULTAS) EJECUTAR MES DE AGOSTO LINEA BASE 25 PERSONAS | K1: ACTIVIDAD 3 CHARLA DE LA MASCULINIDAD POR LA IGUALDAD EJE 2 PLANOVI (JOVENES Y ADOLESCENTES) EJECUTAR MES DE MAYO LÍNEA BASE 100 PERSONAS | O1: ACTIVIDAD 4 CHARLA PREVENCIÓN DE LA MASCULINIDAD POR LA IGUALDAD ADULTOS EJE 2 PLANOVI (COMUNIDAD) EJECUTAR MES DE AGOSTO LÍNEA BASE 15 PERSONAS | S1: ACTIVIDAD 5 CHARLA TRATA DE PERSONAS JOVENES ADOLESCENTES EJE 1 CONATT EJECUTAR MES DE MAYO LÍNEA BASE 50 PERSONAS | W1: ACTIVIDAD 6 CHARLA TRATA DE PERSONAS ADULTOS COMUNIDADES EJE 1 CONATT EJECUTAR MES DE AGOSTO LÍNEA BASE 10 PARTICIPANTES | AA1: ACTIVIDAD 7 CHARLA PREVENCIÓN DEL FEMICIDIO Y DIVULGACION COMITES CLAIS PERSONAS ADULTAS EJE 6 PLANOVI EJECUTAR MES DE OCTUBRE LÍNEA BASE 15 | AE1: ACTIVIDAD 8 ESTRATEGIA DE COMUNICACIÓN EJE 1 PLANOVI PREVENCION DE LA VIOLENCIA CONTRA LAS MUJERES EJECUTAR MES DE MARZO LÍNEA BASE 100 PERSONAS | AI1: ACTIVIDAD 9 ESTRATEGIA DE COMUNICACIÓN EJE 2 PLANOVI MASCULINIDAD POR LA IGUALDAD EJECUTAR MES DE JUNIO LÍNEA BASE 100 PERSONAS | AM1: ACTIVIDAD 10 ESTRATEGIA DE COMUNICACIÓN EJE 5 PLANOVI PREVENCIÓN, ATENCIÓN INTEGRAL Y NO-REVICTIMIZACIÓN FRENTE A LA VIOLENCIA SEXUAL EJECUTAR MES DE SETIEMBRE LÍNEA BASE 100 PERSONAS | AQ1: ACTIVIDAD 11 ESTRATEGIA DE COMUNICACIÓN EJE 6 PLANOVI PREVENCIÓN DEL FEMICIDIO EJECUTAR MES DE NOVIEMBRE LÍNEA BASE 100 PERSONAS | AU1: ACTIVIDAD 12 ESTRATEGIA DE COMUNICACIÓN EJE 1 CONATT CONTRA LA TRATA DE PERSONAS EJECUTAR MES DE JULIO LÍNEA BASE 100 PERSONAS | AY1: ACTIVIDAD 13 ESTRATEGIA DE COMUNICACIÓN EJE 1 CONATT TRAFICO ILICITO PERSONAS MIGRANTES EJECUTAR MES DE DICIEMBRE LÍNEA BASE 100 PERSONAS | BC1: ACTIVIDAD 14 ESTRATEGIA DE COMUNICACIÓN JUSTICIA RESTAURATIVA EJECUTAR MES DE ABRIL 50% COMITÉS SEGURIDAD COMUNITARIA | BG1: ACTIVIDAD 15 ESTRATEGIA DE COMUNICACIÓN JUSTICIA RESTAURATIVA EJECUTAR MES DE ABRIL 50% COMERCIOS | BK1: ACTIVIDAD 16 REPRESENTACION INSTITUCIONAL REDES CONTRA LA VIOLENCIA INTRAFAMILIAR PLANOVI CANTIDAD DE PARTICIPACIÓN POR TRIMESTRE | BO1: ACTIVIDAD 17 REPRESENTACION INSTITUCIONAL SUBSISTEMA LOCAL NIÑEZ Y ADOLESCENCIA (PANI) CANTIDAD DE PARTICIPACIÓN POR TRIMESTRE | BS1: ACTIVIDAD 18 REPRESENTACION INSTITUCIONAL COMITÉ LOCAL CLAIS (PODER JUDICIAL-INAMU-FUERZA PUBLICA) CANTIDAD DE PARTICIPACIÓN POR TRIMESTRE
C2: PRIMER TRIMESTRE | D2: SEGUNDO TRIMESTRE | E2: TERCER TRIMESTRE | F2: CUARTO TRIMESTRE | G2: PRIMER TRIMESTRE | H2: SEGUNDO TRIMESTRE | I2: TERCER TRIMESTRE | J2: CUARTO TRIMESTRE | K2: PRIMER TRIMESTRE | L2: SEGUNDO TRIMESTRE | M2: TERCER TRIMESTRE | N2: CUARTO TRIMESTRE | O2: PRIMER TRIMESTRE | P2: SEGUNDO TRIMESTRE | Q2: TERCER TRIMESTRE | R2: CUARTO TRIMESTRE | S2: PRIMER TRIMESTRE | T2: SEGUNDO TRIMESTRE | U2: TERCER TRIMESTRE | V2: CUARTO TRIMESTRE | W2: PRIMER TRIMESTRE | X2: SEGUNDO TRIMESTRE | Y2: TERCER TRIMESTRE | Z2: CUARTO TRIMESTRE | AA2: PRIMER TRIMESTRE | AB2: SEGUNDO TRIMESTRE | AC2: TERCER TRIMESTRE | AD2: CUARTO TRIMESTRE | AE2: PRIMER TRIMESTRE | AF2: SEGUNDO TRIMESTRE | AG2: TERCER TRIMESTRE | AH2: CUARTO TRIMESTRE | AI2: PRIMER TRIMESTRE | AJ2: SEGUNDO TRIMESTRE | AK2: TERCER TRIMESTRE | AL2: CUARTO TRIMESTRE | AM2: PRIMER TRIMESTRE | AN2: SEGUNDO TRIMESTRE | AO2: TERCER TRIMESTRE | AP2: CUARTO TRIMESTRE | AQ2: PRIMER TRIMESTRE | AR2: SEGUNDO TRIMESTRE | AS2: TERCER TRIMESTRE | AT2: CUARTO TRIMESTRE | AU2: PRIMER TRIMESTRE | AV2: SEGUNDO TRIMESTRE | AW2: TERCER TRIMESTRE | AX2: CUARTO TRIMESTRE | AY2: PRIMER TRIMESTRE | AZ2: SEGUNDO TRIMESTRE | BA2: TERCER TRIMESTRE | BB2: CUARTO TRIMESTRE | BC2: PRIMER TRIMESTRE | BD2: SEGUNDO TRIMESTRE | BE2: TERCER TRIMESTRE | BF2: CUARTO TRIMESTRE | BG2: PRIMER TRIMESTRE | BH2: SEGUNDO TRIMESTRE | BI2: TERCER TRIMESTRE | BJ2: CUARTO TRIMESTRE | BK2: PRIMER TRIMESTRE | BL2: SEGUNDO TRIMESTRE | BM2: TERCER TRIMESTRE | BN2: CUARTO TRIMESTRE | BO2: PRIMER TRIMESTRE | BP2: SEGUNDO TRIMESTRE | BQ2: TERCER TRIMESTRE | BR2: CUARTO TRIMESTRE | BS2: PRIMER TRIMESTRE | BT2: SEGUNDO TRIMESTRE | BU2: TERCER TRIMESTRE | BV2: CUARTO TRIMESTRE
A3: REGIÓN 1 SAN JOSE NORTE | B3: D-10 CURRIDABAT | D3: 125 | L3: 100 | T3: 50 | AE3: 100 | BD3: 1 | BH3: 1 | BK3: 1 | BL3: 3 | BO3: 1 | BP3: 3 | BT3: LLAMAR A COMISION PARA INFORMACIÓN DE LA CONFORMACION
B4: D-11 MONTES DE OCA | D4: 145 | L4: 120 | T4: 80 | AE4: 187 | BD4: 1 | BH4: 1 | BO4: 1 | BS4: SOLICITAR A DOÑA SHIRLEY LA CAPACITACION POR PARTE DEL PJ
B5: D-12 GOICOECHEA | D5: 125 | L5: 100 | T5: 155 | AE5: 129 | BD5: 1 | BH5: 1 | BK5: 2 | BS5: SOLICITAR A DOÑA SHIRLEY LA CAPACITACION POR PARTE DEL PJ
B6: D-13 MORAVIA | D6: 125 | L6: 118 | T6: 60 | AE6: 100 | BD6: 1 | BH6: 1 | BK6: 2 | BL6: 3 | BO6: 1 | BP6: 3 | BS6: SOLICITAR A DOÑA SHIRLEY LA CAPACITACION POR PARTE DEL PJ
B7: D-14 TIBAS | D7: 125 | L7: 100 | T7: 50 | AE7: 100 | BD7: 1 | BH7: 1 | BL7: 3 | BO7: 3 | BP7: 2 | BS7: SOLICITAR A DOÑA SHIRLEY LA CAPACITACION POR PARTE DEL PJ
B8: D-15 CORONADO | D8: 125 | L8: 100 | T8: 50 | AE8: 153 | BD8: 1 | BH8: 1 | BK8: 2 | BL8: 1 | BO8: 3 | BP8: 1 | BS8: SOLICITAR A DOÑA SHIRLEY LA CAPACITACION POR PARTE DEL PJ
C9: =SUM(C3:C8) -> 0 | D9: =SUM(D3:D8) -> 770 | E9: =SUM(E3:E8) -> 0 | F9: =SUM(F3:F8) -> 0 | G9: =SUM(G3:G8) -> 0 | H9: =SUM(H3:H8) -> 0 | I9: =SUM(I3:I8) -> 0 | J9: =SUM(J3:J8) -> 0 | ... BB9: =SUM(BB3:BB8) -> 0 | BK9: =SUM(BK3:BK8) -> 7 | BL9: =SUM(BL3:BL8) -> 10 | BM9: =SUM(BM3:BM8) -> 0 | BN9: =SUM(BN3:BN8) -> 0 | BO9: =SUM(BO3:BO8) -> 9 | BP9: =SUM(BP3:BP8) -> 9 | BQ9: =SUM(BQ3:BQ8) -> 0 | BR9: =SUM(BR3:BR8) -> 0 | ... BV9: =SUM(BV3:BV8) -> 0
B10: TOTAL | C10: =SUM(C9+D9+E9+F9) -> 770 | G10: =SUM(G9+H9+I9+J9) -> 0 | K10: =SUM(K9+L9+M9+N9) -> 638 | O10: =SUM(O9+P9+Q9+R9) -> 0 | S10: =SUM(S9+T9+U9+V9) -> 445 | W10: =SUM(W9+X9+Y9+Z9) -> 0 | AA10: =SUM(AA9+AB9+AC9+AD9) -> 0 | AE10: =SUM(AE9:AH9) -> 769 | AI10: =SUM(AI9+AJ9+AK9+AL9) -> 0 | AM10: =SUM(AM9+AN9+AO9+AP9) -> 0 | AQ10: =SUM(AQ9+AR9+AS9+AT9) -> 0 | AU10: =SUM(AU9:AX9) -> 0 | AY10: =SUM(AY9:BB9) -> 0 | BC10: =SUM(BC9:BF9) -> 0 | BG10: =SUM(BG9:BJ9) -> 0 | BK10: =SUM(BK9:BN9) -> 17 | BO10: =SUM(BO9:BR9) -> 18 | BS10: =SUM(BS9:BV9) -> 0

Sheet REGIÓN 1 SAN JOSÉ SUR
A1: REGION | B1: DELEGACION POLICIAL | C1: ACTIVIDAD 1 CHARLA PREVENCIÓN DE LA VIOLENCIA EN RELACIONES DE PAREJA EJE 1 PLANOVI (JOVENES ADOLESCENTES) EJECUTAR MES DE MAYO LÍNEA BASE 125 PERSONAS | G1: ACTIVIDAD 2 CHARLA PREVENCIÓN DE LA VIOLENCIA DOMÉSTICA E INTRAFAMILIAR EJE 1 PLANOVI (PERSONAS ADULTAS) EJECUTAR MES DE AGOSTO LINEA BASE 25 PERSONAS | K1: ACTIVIDAD 3 CHARLA PREVENCIÓN DE LA MASCULINIDAD POR LA IGUALDAD EJE 2 PLANOVI (JOVENES Y ADOLESCENTES) EJECUTAR MES DE MAYO LÍNEA BASE 100 PERSONAS | O1: ACTIVIDAD 4 CHARLA PREVENCIÓN DE LA MASCULINIDAD POR LA IGUALDAD ADULTOS EJE 2 PLANOVI (COMUNIDAD) EJECUTAR MES DE AGOSTO LÍNEA BASE 15 PERSONAS | S1: ACTIVIDAD 5 CHARLA TRATA DE PERSONAS JOVENES ADOLESCENTES EJE 1 CONATT EJECUTAR MES DE MAYO LÍNEA BASE 50 PERSONAS | W1: ACTIVIDAD 6 CHARLA TRATA DE PERSONAS ADULTOS COMUNIDADES EJE 1 CONATT EJECUTAR MES DE AGOSTO LÍNEA BASE 10 PARTICIPANTES | AA1: ACTIVIDAD 7 CHARLA PREVENCIÓN DEL FEMICIDIO Y DIVULGACION COMITES CLAIS PERSONAS ADULTAS EJE 6 PLANOVI EJECUTAR MES DE OCTUBRE LÍNEA BASE 15 | AE1: ACTIVIDAD 8 ESTRATEGIA DE COMUNICACIÓN EJE 1 PLANOVI PREVENCION DE LA VIOLENCIA CONTRA LAS MUJERES EJECUTAR MES DE MARZO LÍNEA BASE 100 PERSONAS | AI1: ACTIVIDAD 9 ESTRATEGIA DE COMUNICACIÓN EJE 2 PLANOVI MASCULINIDAD POR LA IGUALDAD EJECUTAR MES DE JUNIO LÍNEA BASE 100 PERSONAS | AM1: ACTIVIDAD 10 ESTRATEGIA DE COMUNICACIÓN EJE 5 PLANOVI PREVENCIÓN, ATENCIÓN INTEGRAL Y NO-REVICTIMIZACIÓN FRENTE A LA VIOLENCIA SEXUAL EJECUTAR MES DE SETIEMBRE LÍNEA BASE 100 PERSONAS | AQ1: ACTIVIDAD 11 ESTRATEGIA DE COMUNICACIÓN EJE 6 PLANOVI PREVENCIÓN DEL FEMICIDIO EJECUTAR MES DE NOVIEMBRE LÍNEA BASE 100 PERSONAS | AU1: ACTIVIDAD 12 ESTRATEGIA DE COMUNICACIÓN EJE 1 CONATT CONTRA LA TRATA DE PERSONAS EJECUTAR MES DE JULIO LÍNEA BASE 100 PERSONAS | AY1: ACTIVIDAD 13 ESTRATEGIA DE COMUNICACIÓN EJE 1 CONATT TRAFICO ILICITO PERSONAS MIGRANTES EJECUTAR MES DE DICIEMBRE LÍNEA BASE 100 PERSONAS | BC1: ACTIVIDAD 14 ESTRATEGIA DE COMUNICACIÓN JUSTICIA RESTAURATIVA EJECUTAR MES DE ABRIL 50% COMITÉS SEGURIDAD COMUNITARIA | BG1: ACTIVIDAD 15 ESTRATEGIA DE COMUNICACIÓN JUSTICIA RESTAURATIVA EJECUTAR MES DE ABRIL 50% COMERCIOS | BK1: ACTIVIDAD 16 REPRESENTACION INSTITUCIONAL REDES CONTRA LA VIOLENCIA INTRAFAMILIAR PLANOVI CANTIDAD DE PARTICIPACIÓN POR TRIMESTRE | BO1: ACTIVIDAD 17 REPRESENTACION INSTITUCIONAL SUBSISTEMA LOCAL NIÑEZ Y ADOLESCENCIA (PANI) CANTIDAD DE PARTICIPACIÓN POR TRIMESTRE | BS1: ACTIVIDAD 18 REPRESENTACION INSTITUCIONAL COMITÉ LOCAL CLAIS (PODER JUDICIAL-INAMU-FUERZA PUBLICA) CANTIDAD DE PARTICIPACIÓN POR TRIMESTRE
C2: PRIMER TRIMESTRE | D2: SEGUNDO TRIMESTRE | E2: TERCER TRIMESTRE | F2: CUARTO TRIMESTRE | G2: PRIMER TRIMESTRE | H2: SEGUNDO TRIMESTRE | I2: TERCER TRIMESTRE | J2: CUARTO TRIMESTRE | K2: PRIMER TRIMESTRE | L2: SEGUNDO TRIMESTRE | M2: TERCER TRIMESTRE | N2: CUARTO TRIMESTRE | O2: PRIMER TRIMESTRE | P2: SEGUNDO TRIMESTRE | Q2: TERCER TRIMESTRE | R2: CUARTO TRIMESTRE | S2: PRIMER TRIMESTRE | T2: SEGUNDO TRIMESTRE | U2: TERCER TRIMESTRE | V2: CUARTO TRIMESTRE | W2: PRIMER TRIMESTRE | X2: SEGUNDO TRIMESTRE | Y2: TERCER TRIMESTRE | Z2: CUARTO TRIMESTRE | AA2: PRIMER TRIMESTRE | AB2: SEGUNDO TRIMESTRE | AC2: TERCER TRIMESTRE | AD2: CUARTO TRIMESTRE | AE2: PRIMER TRIMESTRE | AF2: SEGUNDO TRIMESTRE | AG2: TERCER TRIMESTRE | AH2: CUARTO TRIMESTRE | AI2: PRIMER TRIMESTRE | AJ2: SEGUNDO TRIMESTRE | AK2: TERCER TRIMESTRE | AL2: CUARTO TRIMESTRE | AM2: PRIMER TRIMESTRE | AN2: SEGUNDO TRIMESTRE | AO2: TERCER TRIMESTRE | AP2: CUARTO TRIMESTRE | AQ2: PRIMER TRIMESTRE | AR2: SEGUNDO TRIMESTRE | AS2: TERCER TRIMESTRE | AT2: CUARTO TRIMESTRE | AU2: PRIMER TRIMESTRE | AV2: SEGUNDO TRIMESTRE | AW2: TERCER TRIMESTRE | AX2: CUARTO TRIMESTRE | AY2: PRIMER TRIMESTRE | AZ2: SEGUNDO TRIMESTRE | BA2: TERCER TRIMESTRE | BB2: CUARTO TRIMESTRE | BC2: PRIMER TRIMESTRE | BD2: SEGUNDO TRIMESTRE | BE2: TERCER TRIMESTRE | BF2: CUARTO TRIMESTRE | BG2: PRIMER TRIMESTRE | BH2: SEGUNDO TRIMESTRE | BI2: TERCER TRIMESTRE | BJ2: CUARTO TRIMESTRE | BK2: PRIMER TRIMESTRE | BL2: SEGUNDO TRIMESTRE | BM2: TERCER TRIMESTRE | BN2: CUARTO TRIMESTRE | BO2: PRIMER TRIMESTRE | BP2: SEGUNDO TRIMESTRE | BQ2: TERCER TRIMESTRE | BR2: CUARTO TRIMESTRE | BS2: PRIMER TRIMESTRE | BT2: SEGUNDO TRIMESTRE | BU2: TERCER TRIMESTRE | BV2: CUARTO TRIMESTRE
A3: PRIMERA SAN JOSE SUR | B3: D-16 DESAMPARADOS NORTE | D3: 544 | L3: 477 | T3: 291 | AE3: 223 | AK3: 0 | BD3: 1 | BH3: 1 | BK3: 3 | BL3: 2 | BO3: 4 | BP3: 2 | BS3: 1 | BT3: 1
B4: D-17 DESAMPARADOS SUR | D4: 141 | L4: 141 | T4: 70 | AE4: 194 | AK4: 0 | BD4: 1 | BH4: 1 | BK4: 3 | BL4: 2 | BO4: 3 | BP4: 2 | BS4: 1 | BT4: 0
B5: D-18 ASERRI | D5: 208 | L5: 101 | T5: 155 | AE5: 125 | AK5: 0 | BD5: 1 | BH5: 1 | BK5: 1 | BL5: 2 | BP5: 1
B6: D-19 ACOSTA | D6: 127 | L6: 100 | T6: 50 | AE6: 198 | AK6: 161 | BD6: 1 | BH6: 1 | BK6: 1 | BL6: 3 | BP6: 0
B7: D-20 ALAJUELITA | D7: 125 | L7: 100 | T7: 50 | AE7: 300 | AK7: 100 | BD7: 1 | BH7: 1 | BK7: 2 | BL7: 0 | BO7: 2 | BP7: 0 | BT7: 0
B8: D-21 ESCAZU | D8: 126 | L8: 103 | T8: 50 | AE8: 158 | AK8: 158 | BD8: 1 | BH8: 1 | BK8: 1 | BL8: 3 | BO8: 1 | BP8: 3
B9: D-22 SANTA ANA | D9: 142 | L9: 102 | T9: 95 | AK9: 0 | BD9: 1 | BH9: 1 | BL9: 2 | BP9: 0
B10: D-23 MORA | D10: 130 | L10: 114 | T10: 57 | AE10: 2273 | AK10: 2196 | BD10: 1 | BH10: 1 | BK10: 2 | BL10: 3 | BO10: 1 | BP10: 3
B11: D-24 PURISCAL | D11: 125 | L11: 119 | T11: 54 | AE11: 394 | AK11: 394 | BD11: 1 | BH11: 1 | BK11: 1 | BL11: 2 | BP11: 1
B12: D-25 TURRUBARES | D12: 126 | L12: 105 | T12: 51 | AE12: 277 | AK12: 0 | BD12: 1 | BH12: 1 | BO12: 3 | BP12: 2
C13: =SUM(C3:C12) -> 0 | D13: =SUM(D3:D12) -> 1794 | E13: =SUM(E3:E12) -> 0 | F13: =SUM(F3:F12) -> 0 | G13: =SUM(G3:G12) -> 0 | H13: =SUM(H3:H12) -> 0 | I13: =SUM(I3:I12) -> 0 | J13: =SUM(J3:J12) -> 0 | ... BB13: =SUM(BB3:BB12) -> 0 | BD13: 1 | BH13: 1 | BK13: =SUM(BK3:BK12) -> 14 | BL13: =SUM(BL3:BL12) -> 19 | BM13: =SUM(BM3:BM12) -> 0 | BN13: =SUM(BN3:BN12) -> 0 | BO13: =SUM(BO3:BO12) -> 14 | BP13: =SUM(BP3:BP12) -> 14 | BQ13: =SUM(BQ3:BQ12) -> 0 | BR13: =SUM(BR3:BR12) -> 0 | ... BV13: =SUM(BV3:BV12) -> 0
B14: TOTAL | C14: =SUM(C13+D13+E13+F13) -> 1794 | G14: =SUM(G13+H13+I13+J13) -> 0 | K14: =SUM(K13+L13+M13+N13) -> 1462 | O14: =SUM(O13+P13+Q13+R13) -> 0 | S14: =SUM(S13+T13+U13+V13) -> 923 | W14: =SUM(W13+X13+Y13+Z13) -> 0 | AA14: =SUM(AA13+AB13+AC13+AD13) -> 0 | AE14: =SUM(AE13:AH13) -> 4142 | AI14: =SUM(AI13+AJ13+AK13+AL13) -> 3009 | AM14: =SUM(AM13+AN13+AO13+AP13) -> 0 | AQ14: =SUM(AQ13+AR13+AS13+AT13) -> 0 | AU14: =SUM(AU13:AX13) -> 0 | AY14: =SUM(AY13:BB13) -> 0 | BC14: 1 | BG14: 1 | BK14: =SUM(BK13:BN13) -> 33 | BO14: =SUM(BO13:BR13) -> 28 | BS14: =SUM(BS13:BV13) -> 3

Sheet REGION 2 ALAJUELA
A1: REGION | B1: DELEGACION POLICIAL | C1: ACTIVIDAD 1 CHARLA PREVENCIÓN DE LA VIOLENCIA EN RELACIONES DE PAREJA EJE 1 PLANOVI (JOVENES ADOLESCENTES) EJECUTAR MES DE MAYO LÍNEA BASE 100 PERSONAS | G1: ACTIVIDAD 2 CHARLA PREVENCIÓN DE LA VIOLENCIA DOMÉSTICA E INTRAFAMILIAR EJE 1 PLANOVI (PERSONAS ADULTAS) EJECUTAR MES DE AGOSTO LINEA BASE 25 PERSONAS | K1: ACTIVIDAD 3 CHARLA PREVENCIÓN DE LA MASCULINIDAD POR LA IGUALDAD EJE 2 PLANOVI (JOVENES Y ADOLESCENTES) EJECUTAR MES DE MAYO LÍNEA BASE 75 PERSONAS | O1: ACTIVIDAD 4 CHARLA PREVENCIÓN DE LA MASCULINIDAD POR LA IGUALDAD ADULTOS EJE 2 PLANOVI (COMUNIDAD) EJECUTAR MES DE AGOSTO LÍNEA BASE 15 PERSONAS | S1: ACTIVIDAD 5 CHARLA TRATA DE PERSONAS JOVENES ADOLESCENTES EJE 1 CONATT EJECUTAR MES DE MAYO LÍNEA BASE 50 PERSONAS | W1: ACTIVIDAD 6 CHARLA TRATA DE PERSONAS ADULTOS COMUNIDADES EJE 1 CONATT EJECUTAR MES DE AGOSTO LÍNEA BASE 10 PARTICIPANTES | AA1: ACTIVIDAD 7 CHARLA PREVENCIÓN DEL FEMICIDIO Y DIVULGACION COMITES CLAIS PERSONAS ADULTAS EJE 6 PLANOVI EJECUTAR MES DE OCTUBRE LÍNEA BASE 15 | AE1: ACTIVIDAD 8 ESTRATEGIA DE COMUNICACIÓN EJE 1 PLANOVI PREVENCION DE LA VIOLENCIA CONTRA LAS MUJERES EJECUTAR MES DE MARZO LÍNEA BASE 100 PERSONAS | AI1: ACTIVIDAD 9 ESTRATEGIA DE COMUNICACIÓN EJE 2 PLANOVI MASCULINIDAD POR LA IGUALDAD EJECUTAR MES DE JUNIO LÍNEA BASE 100 PERSONAS | AM1: ACTIVIDAD 10 ESTRATEGIA DE COMUNICACIÓN EJE 5 PLANOVI PREVENCIÓN, ATENCIÓN INTEGRAL Y NO-REVICTIMIZACIÓN FRENTE A LA VIOLENCIA SEXUAL EJECUTAR MES DE SETIEMBRE LÍNEA BASE 100 PERSONAS | AQ1: ACTIVIDAD 11 ESTRATEGIA DE COMUNICACIÓN EJE 6 PLANOVI PREVENCIÓN DEL FEMICIDIO EJECUTAR MES DE NOVIEMBRE LÍNEA BASE 100 PERSONAS | AU1: ACTIVIDAD 12 ESTRATEGIA DE COMUNICACIÓN EJE 1 CONATT CONTRA LA TRATA DE PERSONAS EJECUTAR MES DE JULIO LÍNEA BASE 100 PERSONAS | AY1: ACTIVIDAD 13 ESTRATEGIA DE COMUNICACIÓN EJE 1 CONATT TRAFICO ILICITO PERSONAS MIGRANTES EJECUTAR MES DE DICIEMBRE LÍNEA BASE 100 PERSONAS | BC1: ACTIVIDAD 14 ESTRATEGIA DE COMUNICACIÓN JUSTICIA RESTAURATIVA EJECUTAR MES DE ABRIL 50% COMITÉS SEGURIDAD COMUNITARIA | BG1: ACTIVIDAD 15 ESTRATEGIA DE COMUNICACIÓN JUSTICIA RESTAURATIVA EJECUTAR MES DE ABRIL 50% COMERCIOS | BK1: ACTIVIDAD 16 REPRESENTACION INSTITUCIONAL REDES CONTRA LA VIOLENCIA INTRAFAMILIAR PLANOVI CANTIDAD DE PARTICIPACIÓN POR TRIMESTRE | BO1: ACTIVIDAD 17 REPRESENTACION INSTITUCIONAL SUBSISTEMA LOCAL NIÑEZ Y ADOLESCENCIA (PANI) CANTIDAD DE PARTICIPACIÓN POR TRIMESTRE | BS1: ACTIVIDAD 18 REPRESENTACION INSTITUCIONAL COMITÉ LOCAL CLAIS (PODER JUDICIAL-INAMU-FUERZA PUBLICA) CANTIDAD DE PARTICIPACIÓN POR TRIMESTRE
C2: PRIMER TRIMESTRE | D2: SEGUNDO TRIMESTRE | E2: TERCER TRIMESTRE | F2: CUARTO TRIMESTRE | G2: PRIMER TRIMESTRE | H2: SEGUNDO TRIMESTRE | I2: TERCER TRIMESTRE | J2: CUARTO TRIMESTRE | K2: PRIMER TRIMESTRE | L2: SEGUNDO TRIMESTRE | M2: TERCER TRIMESTRE | N2: CUARTO TRIMESTRE | O2: PRIMER TRIMESTRE | P2: SEGUNDO TRIMESTRE | Q2: TERCER TRIMESTRE | R2: CUARTO TRIMESTRE | S2: PRIMER TRIMESTRE | T2: SEGUNDO TRIMESTRE | U2: TERCER TRIMESTRE | V2: CUARTO TRIMESTRE | W2: PRIMER TRIMESTRE | X2: SEGUNDO TRIMESTRE | Y2: TERCER TRIMESTRE | Z2: CUARTO TRIMESTRE | AA2: PRIMER TRIMESTRE | AB2: SEGUNDO TRIMESTRE | AC2: TERCER TRIMESTRE | AD2: CUARTO TRIMESTRE | AE2: PRIMER TRIMESTRE | AF2: SEGUNDO TRIMESTRE | AG2: TERCER TRIMESTRE | AH2: CUARTO TRIMESTRE | AI2: PRIMER TRIMESTRE | AJ2: SEGUNDO TRIMESTRE | AK2: TERCER TRIMESTRE | AL2: CUARTO TRIMESTRE | AM2: PRIMER TRIMESTRE | AN2: SEGUNDO TRIMESTRE | AO2: TERCER TRIMESTRE | AP2: CUARTO TRIMESTRE | AQ2: PRIMER TRIMESTRE | AR2: SEGUNDO TRIMESTRE | AS2: TERCER TRIMESTRE | AT2: CUARTO TRIMESTRE | AU2: PRIMER TRIMESTRE | AV2: SEGUNDO TRIMESTRE | AW2: TERCER TRIMESTRE | AX2: CUARTO TRIMESTRE | AY2: PRIMER TRIMESTRE | AZ2: SEGUNDO TRIMESTRE | BA2: TERCER TRIMESTRE | BB2: CUARTO TRIMESTRE | BC2: PRIMER TRIMESTRE | BD2: SEGUNDO TRIMESTRE | BE2: TERCER TRIMESTRE | BF2: CUARTO TRIMESTRE | BG2: PRIMER TRIMESTRE | BH2: SEGUNDO TRIMESTRE | BI2: TERCER TRIMESTRE | BJ2: CUARTO TRIMESTRE | BK2: PRIMER TRIMESTRE | BL2: SEGUNDO TRIMESTRE | BM2: TERCER TRIMESTRE | BN2: CUARTO TRIMESTRE | BO2: PRIMER TRIMESTRE | BP2: SEGUNDO TRIMESTRE | BQ2: TERCER TRIMESTRE | BR2: CUARTO TRIMESTRE | BS2: PRIMER TRIMESTRE | BT2: SEGUNDO TRIMESTRE | BU2: TERCER TRIMESTRE | BV2: CUARTO TRIMESTRE
A3: REGION 2 ALAJUELA | B3: D-26 ALAJUELA sur | D3: 125 | L3: 100 | T3: 50 | AJ3: 500 | BD3: 1 | BH3: 1 | BK3: 2 | BL3: 2 | BO3: 1 | BP3: 2 | BS3: 1 | BT3: 1
B4: D-27 ALAJUELA NORTE | D4: 125 | L4: 116 | T4: 50 | AE4: 345 | AF4: 45 | AJ4: 0 | BD4: 1 | BH4: 1 | BK4: 2 | BL4: 3 | BP4: 2 | BS4: 1 | BT4: 1
B5: D-28 SAN RAMON | D5: 127 | L5: 101 | T5: 52 | AE5: 242 | AJ5: 223 | BD5: 1 | BH5: 1 | BK5: 1 | BL5: 2 | BO5: 2 | BP5: 1
B6: D-29 GRECIA | D6: 125 | L6: 100 | T6: 93 | AE6: 433 | AJ6: 0 | BD6: 1 | BH6: 1 | BL6: 0 | BP6: 0
B7: D-30 SAN MATEO | D7: 140 | L7: 100 | T7: 59 | AJ7: 0 | BD7: 1 | BH7: 1 | BL7: 2 | BP7: 2
B8: D-31 ATENAS | D8: 150 | L8: 120 | T8: 150 | AE8: 100 | AJ8: 0 | BD8: 1 | BH8: 1 | BL8: 1 | BO8: 1 | BP8: 3
B9: D-32 NARANJO | D9: 178 | L9: 145 | T9: 98 | AE9: 167 | AJ9: 255 | BD9: 1 | BH9: 1 | BK9: 2 | BL9: 1 | BO9: 2 | BP9: 3
B10: D-33 PALMARES | D10: 161 | L10: 131 | T10: 63 | AE10: 258 | AJ10: 0 | BD10: 1 | BH10: 1 | BL10: 3 | BP10: 0
B11: D-34 POAS | D11: 143 | L11: 139 | T11: 51 | AE11: 226 | AJ11: 0 | BD11: 1 | BH11: 1 | BK11: 2 | BL11: 1 | BO11: 1 | BP11: 3
B12: D-35 OROTINA | D12: 125 | L12: 124 | T12: 57 | AE12: 323 | AJ12: 0 | BD12: 1 | BH12: 1 | BK12: 2 | BL12: 1 | BO12: 2 | BP12: 1
B13: D-36 SARCHI | D13: 125 | L13: 100 | T13: 50 | AE13: 100 | AJ13: 0 | BD13: 1 | BH13: 1 | BK13: 1 | BL13: 1 | BO13: 2 | BP13: 1
C14: =SUM(C4:C13) -> 0 | D14: =SUM(D4:D13) -> 1399 | E14: =SUM(E4:E13) -> 0 | F14: =SUM(F4:F13) -> 0 | G14: =SUM(G4:G13) -> 0 | H14: =SUM(H4:H13) -> 0 | I14: =SUM(I4:I13) -> 0 | J14: =SUM(J4:J13) -> 0 | ... BB14: =SUM(BB4:BB13) -> 0 | BK14: =SUM(BK4:BK13) -> 10 | BL14: =SUM(BL4:BL13) -> 15 | BM14: =SUM(BM4:BM13) -> 0 | BN14: =SUM(BN4:BN13) -> 0 | BO14: =SUM(BO4:BO13) -> 10 | BP14: =SUM(BP4:BP13) -> 16 | BQ14: =SUM(BQ4:BQ13) -> 0 | BR14: =SUM(BR4:BR13) -> 0 | ... BV14: =SUM(BV4:BV13) -> 0
B15: TOTAL | C15: =SUM(C14+D14+E14+F14) -> 1399 | G15: =SUM(G14+H14+I14+J14) -> 0 | K15: =SUM(K14+L14+M14+N14) -> 1176 | O15: =SUM(O14+P14+Q14+R14) -> 0 | S15: =SUM(S14+T14+U14+V14) -> 723 | W15: =SUM(W14+X14+Y14+Z14) -> 0 | AA15: =SUM(AA14+AB14+AC14+AD14) -> 0 | AE15: =SUM(AE14:AH14) -> 2239 | AI15: =SUM(AI14+AJ14+AK14+AL14) -> 478 | AM15: =SUM(AM14+AN14+AO14+AP14) -> 0 | AQ15: =SUM(AQ14+AR14+AS14+AT14) -> 0 | AU15: =SUM(AU14:AX14) -> 0 | AY15: =SUM(AY14:BB14) -> 0 | BC15: 1 | BG15: 1 | BK15: =SUM(BK14:BN14) -> 25 | BO15: =SUM(BO14:BR14) -> 26 | BS15: =SUM(BS14:BV14) -> 2

Sheet REGION 3 CARTAGO
A1: REGION | B1: DELEGACION POLICIAL | C1: ACTIVIDAD 1 CHARLA PREVENCIÓN DE LA VIOLENCIA EN RELACIONES DE PAREJA EJE 1 PLANOVI (JOVENES ADOLESCENTES) EJECUTAR MES DE MAYO LÍNEA BASE 125 PERSONAS | G1: ACTIVIDAD 2 CHARLA PREVENCIÓN DE LA VIOLENCIA DOMÉSTICA E INTRAFAMILIAR EJE 1 PLANOVI (PERSONAS ADULTAS) EJECUTAR MES DE AGOSTO LINEA BASE 25 PERSONAS | K1: ACTIVIDAD 3 CHARLA PREVENCIÓN DE LA MASCULINIDAD POR LA IGUALDAD EJE 2 PLANOVI (JOVENES Y ADOLESCENTES) EJECUTAR MES DE MAYO LÍNEA BASE 100 PERSONAS | O1: ACTIVIDAD 4 CHARLA PREVENCIÓN DE LA MASCULINIDAD POR LA IGUALDAD ADULTOS EJE 2 PLANOVI (COMUNIDAD) EJECUTAR MES DE AGOSTO LÍNEA BASE 15 PERSONAS | S1: ACTIVIDAD 5 CHARLA TRATA DE PERSONAS JOVENES ADOLESCENTES EJE 1 CONATT EJECUTAR MES DE MAYO LÍNEA BASE 50 PERSONAS | W1: ACTIVIDAD 6 CHARLA TRATA DE PERSONAS ADULTOS COMUNIDADES EJE 1 CONATT EJECUTAR MES DE AGOSTO LÍNEA BASE 10 PARTICIPANTES | AA1: ACTIVIDAD 7 CHARLA PREVENCIÓN DEL FEMICIDIO Y DIVULGACION COMITES CLAIS PERSONAS ADULTAS EJE 6 PLANOVI EJECUTAR MES DE OCTUBRE LÍNEA BASE 15 | AE1: ACTIVIDAD 8 ESTRATEGIA DE COMUNICACIÓN EJE 1 PLANOVI PREVENCION DE LA VIOLENCIA CONTRA LAS MUJERES EJECUTAR MES DE MARZO LÍNEA BASE 100 PERSONAS | AI1: ACTIVIDAD 9 ESTRATEGIA DE COMUNICACIÓN EJE 2 PLANOVI MASCULINIDAD POR LA IGUALDAD EJECUTAR MES DE JUNIO LÍNEA BASE 100 PERSONAS | AM1: ACTIVIDAD 10 ESTRATEGIA DE COMUNICACIÓN EJE 5 PLANOVI PREVENCIÓN, ATENCIÓN INTEGRAL Y NO-REVICTIMIZACIÓN FRENTE A LA VIOLENCIA SEXUAL EJECUTAR MES DE SETIEMBRE LÍNEA BASE 100 PERSONAS | AQ1: ACTIVIDAD 11 ESTRATEGIA DE COMUNICACIÓN EJE 6 PLANOVI PREVENCIÓN DEL FEMICIDIO EJECUTAR MES DE NOVIEMBRE LÍNEA BASE 100 PERSONAS | AU1: ACTIVIDAD 12 ESTRATEGIA DE COMUNICACIÓN EJE 1 CONATT CONTRA LA TRATA DE PERSONAS EJECUTAR MES DE JULIO LÍNEA BASE 100 PERSONAS | AY1: ACTIVIDAD 13 ESTRATEGIA DE COMUNICACIÓN EJE 1 CONATT TRAFICO ILICITO PERSONAS MIGRANTES EJECUTAR MES DE DICIEMBRE LÍNEA BASE 100 PERSONAS | BC1: ACTIVIDAD 14 ESTRATEGIA DE COMUNICACIÓN JUSTICIA RESTAURATIVA EJECUTAR MES DE ABRIL 50% COMITÉS SEGURIDAD COMUNITARIA | BG1: ACTIVIDAD 15 ESTRATEGIA DE COMUNICACIÓN JUSTICIA RESTAURATIVA EJECUTAR MES DE ABRIL 50% COMERCIOS | BK1: ACTIVIDAD 16 REPRESENTACION INSTITUCIONAL REDES CONTRA LA VIOLENCIA INTRAFAMILIAR PLANOVI CANTIDAD DE PARTICIPACIÓN POR TRIMESTRE | BO1: ACTIVIDAD 17 REPRESENTACION INSTITUCIONAL SUBSISTEMA LOCAL NIÑEZ Y ADOLESCENCIA (PANI) CANTIDAD DE PARTICIPACIÓN POR TRIMESTRE | BS1: ACTIVIDAD 18 REPRESENTACION INSTITUCIONAL COMITÉ LOCAL CLAIS (PODER JUDICIAL-INAMU-FUERZA PUBLICA) CANTIDAD DE PARTICIPACIÓN POR TRIMESTRE
C2: PRIMER TRIMESTRE | D2: SEGUNDO TRIMESTRE | E2: TERCER TRIMESTRE | F2: CUARTO TRIMESTRE | G2: PRIMER TRIMESTRE | H2: SEGUNDO TRIMESTRE | I2: TERCER TRIMESTRE | J2: CUARTO TRIMESTRE | K2: PRIMER TRIMESTRE | L2: SEGUNDO TRIMESTRE | M2: TERCER TRIMESTRE | N2: CUARTO TRIMESTRE | O2: PRIMER TRIMESTRE | P2: SEGUNDO TRIMESTRE | Q2: TERCER TRIMESTRE | R2: CUARTO TRIMESTRE | S2: PRIMER TRIMESTRE | T2: SEGUNDO TRIMESTRE | U2: TERCER TRIMESTRE | V2: CUARTO TRIMESTRE | W2: PRIMER TRIMESTRE | X2: SEGUNDO TRIMESTRE | Y2: TERCER TRIMESTRE | Z2: CUARTO TRIMESTRE | AA2: PRIMER TRIMESTRE | AB2: SEGUNDO TRIMESTRE | AC2: TERCER TRIMESTRE | AD2: CUARTO TRIMESTRE | AE2: PRIMER TRIMESTRE | AF2: SEGUNDO TRIMESTRE | AG2: TERCER TRIMESTRE | AH2: CUARTO TRIMESTRE | AI2: PRIMER TRIMESTRE | AJ2: SEGUNDO TRIMESTRE | AK2: TERCER TRIMESTRE | AL2: CUARTO TRIMESTRE | AM2: PRIMER TRIMESTRE | AN2: SEGUNDO TRIMESTRE | AO2: TERCER TRIMESTRE | AP2: CUARTO TRIMESTRE | AQ2: PRIMER TRIMESTRE | AR2: SEGUNDO TRIMESTRE | AS2: TERCER TRIMESTRE | AT2: CUARTO TRIMESTRE | AU2: PRIMER TRIMESTRE | AV2: SEGUNDO TRIMESTRE | AW2: TERCER TRIMESTRE | AX2: CUARTO TRIMESTRE | AY2: PRIMER TRIMESTRE | AZ2: SEGUNDO TRIMESTRE | BA2: TERCER TRIMESTRE | BB2: CUARTO TRIMESTRE | BC2: PRIMER TRIMESTRE | BD2: SEGUNDO TRIMESTRE | BE2: TERCER TRIMESTRE | BF2: CUARTO TRIMESTRE | BG2: PRIMER TRIMESTRE | BH2: SEGUNDO TRIMESTRE | BI2: TERCER TRIMESTRE | BJ2: CUARTO TRIMESTRE | BK2: PRIMER TRIMESTRE | BL2: SEGUNDO TRIMESTRE | BM2: TERCER TRIMESTRE | BN2: CUARTO TRIMESTRE | BO2: PRIMER TRIMESTRE | BP2: SEGUNDO TRIMESTRE | BQ2: TERCER TRIMESTRE | BR2: CUARTO TRIMESTRE | BS2: PRIMER TRIMESTRE | BT2: SEGUNDO TRIMESTRE | BU2: TERCER TRIMESTRE | BV2: CUARTO TRIMESTRE
A3: REGION 3 CARTAGO | B3: D-37 CARTAGO | D3: 160 | L3: 160 | T3: 160 | AE3: 100 | AJ3: 0 | BD3: 1 | BH3: 1 | BK3: 1 | BL3: 4 | BO3: 1 | BP3: 1
B4: D-38 PARAISO | D4: 158 | L4: 153 | T4: 50 | AE4: 140 | AJ4: 0 | BD4: 1 | BH4: 1 | BK4: 2 | BL4: 2 | BO4: 3 | BP4: 2
B5: D-39 LA UNION | D5: 125 | L5: 100 | T5: 50 | AE5: 100 | AJ5: 0 | BD5: 1 | BH5: 1 | BK5: 1 | BL5: 1 | BO5: 1 | BP5: 1
B6: D-40 JIMENEZ | D6: 125 | L6: 100 | T6: 50 | AE6: 176 | AJ6: 0 | BD6: 1 | BH6: 1 | BL6: 3 | BO6: 1 | BP6: 1 | BS6: 1 | BT6: 1
B7: D-41 TURRIALBA | D7: 125 | L7: 100 | T7: 50 | AE7: 100 | AJ7: 0 | BD7: 1 | BH7: 1 | BK7: 3 | BL7: 1 | BO7: 2 | BP7: 1 | BS7: 1 | BT7: 1
B8: D-42 ALVARADO | D8: 100 | L8: 65 | T8: 58 | AE8: 100 | AJ8: 0 | BD8: 1 | BH8: 1 | BO8: 1 | BP8: 2
B9: D-43 OREAMUNO | D9: 128 | L9: 128 | T9: 128 | AE9: 100 | AJ9: 0 | BD9: 1 | BH9: 1 | BK9: 2 | BL9: 2 | BO9: 2 | BP9: 2
B10: D-44 EL GUARCO | D10: 125 | L10: 100 | T10: 50 | AE10: 100 | AJ10: 0 | BD10: 1 | BH10: 1 | BK10: 2 | BL10: 1 | BO10: 1 | BP10: 1
B11: D-45 TARRAZU | D11: 158 | L11: 129 | T11: 127 | AE11: 116 | AJ11: 0 | BD11: 1 | BH11: 1 | BK11: 1 | BL11: 1 | BO11: 1 | BP11: 2 | BT11: 0
B12: D-46 DOTA | D12: 125 | L12: 100 | T12: 50 | AE12: 150 | AJ12: 0 | BD12: 1 | BH12: 1 | BL12: 1 | BO12: 1 | BP12: 2 | BT12: 0
B13: D-47 LEON CORTES | D13: 179 | L13: 179 | T13: 86 | AE13: 187 | AJ13: 0 | BD13: 1 | BH13: 1 | BK13: 1 | BL13: 1 | BO13: 1 | BP13: 1 | BT13: 0
B14: D-48 GUADALUPE | D14: 161 | L14: 110 | T14: 70 | AE14: 100 | AJ14: 0 | BD14: 1 | BH14: 1
C15: =SUM(C3:C14) -> 0 | D15: =SUM(D3:D14) -> 1669 | E15: =SUM(E3:E14) -> 0 | F15: =SUM(F3:F14) -> 0 | G15: =SUM(G3:G14) -> 0 | H15: =SUM(H3:H14) -> 0 | I15: =SUM(I3:I14) -> 0 | J15: =SUM(J3:J14) -> 0 | ... BB15: =SUM(BB3:BB14) -> 0 | BD15: 1 | BH15: 1 | BK15: =SUM(BK3:BK14) -> 13 | BL15: =SUM(BL3:BL14) -> 17 | BM15: =SUM(BM3:BM14) -> 0 | BN15: =SUM(BN3:BN14) -> 0 | BO15: =SUM(BO3:BO14) -> 15 | BP15: =SUM(BP3:BP14) -> 16 | BQ15: =SUM(BQ3:BQ14) -> 0 | BR15: =SUM(BR3:BR14) -> 0 | ... BV15: =SUM(BV3:BV14) -> 0
B16: TOTAL | C16: =SUM(C15+D15+E15+F15) -> 1669 | G16: =SUM(G15+H15+I15+J15) -> 0 | K16: =SUM(K15+L15+M15+N15) -> 1424 | O16: =SUM(O15+P15+Q15+R15) -> 0 | S16: =SUM(S15+T15+U15+V15) -> 929 | W16: =SUM(W15+X15+Y15+Z15) -> 0 | AA16: =SUM(AA15+AB15+AC15+AD15) -> 0 | AE16: =SUM(AE15:AH15) -> 1469 | AI16: =SUM(AI15+AJ15+AK15+AL15) -> 0 | AM16: =SUM(AM15+AN15+AO15+AP15) -> 0 | AQ16: =SUM(AQ15+AR15+AS15+AT15) -> 0 | AU16: =SUM(AU15:AX15) -> 0 | AY16: =SUM(AY15:BB15) -> 0 | BC16: 1 | BG16: 1 | BK16: =SUM(BK15:BN15) -> 30 | BO16: =SUM(BO15:BR15) -> 31 | BS16: =SUM(BS15:BV15) -> 4

Sheet REGION 4 HEREDIA
A1: REGION | B1: DELEGACION POLICIAL | C1: ACTIVIDAD 1 CHARLA PREVENCIÓN DE LA VIOLENCIA EN RELACIONES DE PAREJA EJE 1 PLANOVI (JOVENES ADOLESCENTES) EJECUTAR MES DE MAYO LÍNEA BASE 100 PERSONAS | G1: ACTIVIDAD 2 CHARLA PREVENCIÓN DE LA VIOLENCIA DOMÉSTICA E INTRAFAMILIAR EJE 1 PLANOVI (PERSONAS ADULTAS) EJECUTAR MES DE AGOSTO LINEA BASE 25 PERSONAS | K1: ACTIVIDAD 3 CHARLA PREVENCIÓN DE LA MASCULINIDAD POR LA IGUALDAD EJE 2 PLANOVI (JOVENES Y ADOLESCENTES) EJECUTAR MES DE MAYO LÍNEA BASE 75 PERSONAS | O1: ACTIVIDAD 4 CHARLA PREVENCIÓN DE LA MASCULINIDAD POR LA IGUALDAD ADULTOS EJE 2 PLANOVI (COMUNIDAD) EJECUTAR MES DE AGOSTO LÍNEA BASE 15 PERSONAS | S1: ACTIVIDAD 5 CHARLA TRATA DE PERSONAS JOVENES ADOLESCENTES EJE 1 CONATT EJECUTAR MES DE MAYO LÍNEA BASE 50 PERSONAS | W1: ACTIVIDAD 6 CHARLA TRATA DE PERSONAS ADULTOS COMUNIDADES EJE 1 CONATT EJECUTAR MES DE AGOSTO LÍNEA BASE 10 PARTICIPANTES | AA1: ACTIVIDAD 7 CHARLA PREVENCIÓN DEL FEMICIDIO Y DIVULGACION COMITES CLAIS PERSONAS ADULTAS EJE 6 PLANOVI EJECUTAR MES DE OCTUBRE LÍNEA BASE 15 | AE1: ACTIVIDAD 8 ESTRATEGIA DE COMUNICACIÓN EJE 1 PLANOVI PREVENCION DE LA VIOLENCIA CONTRA LAS MUJERES EJECUTAR MES DE MARZO LÍNEA BASE 100 PERSONAS | AI1: ACTIVIDAD 9 ESTRATEGIA DE COMUNICACIÓN EJE 2 PLANOVI MASCULINIDAD POR LA IGUALDAD EJECUTAR MES DE JUNIO LÍNEA BASE 100 PERSONAS | AM1: ACTIVIDAD 10 ESTRATEGIA DE COMUNICACIÓN EJE 5 PLANOVI PREVENCIÓN, ATENCIÓN INTEGRAL Y NO-REVICTIMIZACIÓN FRENTE A LA VIOLENCIA SEXUAL EJECUTAR MES DE SETIEMBRE LÍNEA BASE 100 PERSONAS | AQ1: ACTIVIDAD 11 ESTRATEGIA DE COMUNICACIÓN EJE 6 PLANOVI PREVENCIÓN DEL FEMICIDIO EJECUTAR MES DE NOVIEMBRE LÍNEA BASE 100 PERSONAS | AU1: ACTIVIDAD 12 ESTRATEGIA DE COMUNICACIÓN EJE 1 CONATT CONTRA LA TRATA DE PERSONAS EJECUTAR MES DE JULIO LÍNEA BASE 100 PERSONAS | AY1: ACTIVIDAD 13 ESTRATEGIA DE COMUNICACIÓN EJE 1 CONATT TRAFICO ILICITO PERSONAS MIGRANTES EJECUTAR MES DE DICIEMBRE LÍNEA BASE 100 PERSONAS | BC1: ACTIVIDAD 14 ESTRATEGIA DE COMUNICACIÓN JUSTICIA RESTAURATIVA EJECUTAR MES DE ABRIL 50% COMITÉS SEGURIDAD COMUNITARIA | BG1: ACTIVIDAD 15 ESTRATEGIA DE COMUNICACIÓN JUSTICIA RESTAURATIVA EJECUTAR MES DE ABRIL 50% COMERCIOS | BK1: ACTIVIDAD 16 REPRESENTACION INSTITUCIONAL REDES CONTRA LA VIOLENCIA INTRAFAMILIAR PLANOVI CANTIDAD DE PARTICIPACIÓN POR TRIMESTRE | BO1: ACTIVIDAD 17 REPRESENTACION INSTITUCIONAL SUBSISTEMA LOCAL NIÑEZ Y ADOLESCENCIA (PANI) CANTIDAD DE PARTICIPACIÓN POR TRIMESTRE | BS1: ACTIVIDAD 18 REPRESENTACION INSTITUCIONAL COMITÉ LOCAL CLAIS (PODER JUDICIAL-INAMU-FUERZA PUBLICA) CANTIDAD DE PARTICIPACIÓN POR TRIMESTRE
C2: PRIMER TRIMESTRE | D2: SEGUNDO TRIMESTRE | E2: TERCER TRIMESTRE | F2: CUARTO TRIMESTRE | G2: PRIMER TRIMESTRE | H2: SEGUNDO TRIMESTRE | I2: TERCER TRIMESTRE | J2: CUARTO TRIMESTRE | K2: PRIMER TRIMESTRE | L2: SEGUNDO TRIMESTRE | M2: TERCER TRIMESTRE | N2: CUARTO TRIMESTRE | O2: PRIMER TRIMESTRE | P2: SEGUNDO TRIMESTRE | Q2: TERCER TRIMESTRE | R2: CUARTO TRIMESTRE | S2: PRIMER TRIMESTRE | T2: SEGUNDO TRIMESTRE | U2: TERCER TRIMESTRE | V2: CUARTO TRIMESTRE | W2: PRIMER TRIMESTRE | X2: SEGUNDO TRIMESTRE | Y2: TERCER TRIMESTRE | Z2: CUARTO TRIMESTRE | AA2: PRIMER TRIMESTRE | AB2: SEGUNDO TRIMESTRE | AC2: TERCER TRIMESTRE | AD2: CUARTO TRIMESTRE | AE2: PRIMER TRIMESTRE | AF2: SEGUNDO TRIMESTRE | AG2: TERCER TRIMESTRE | AH2: CUARTO TRIMESTRE | AI2: PRIMER TRIMESTRE | AJ2: SEGUNDO TRIMESTRE | AK2: TERCER TRIMESTRE | AL2: CUARTO TRIMESTRE | AM2: PRIMER TRIMESTRE | AN2: SEGUNDO TRIMESTRE | AO2: TERCER TRIMESTRE | AP2: CUARTO TRIMESTRE | AQ2: PRIMER TRIMESTRE | AR2: SEGUNDO TRIMESTRE | AS2: TERCER TRIMESTRE | AT2: CUARTO TRIMESTRE | AU2: PRIMER TRIMESTRE | AV2: SEGUNDO TRIMESTRE | AW2: TERCER TRIMESTRE | AX2: CUARTO TRIMESTRE | AY2: PRIMER TRIMESTRE | AZ2: SEGUNDO TRIMESTRE | BA2: TERCER TRIMESTRE | BB2: CUARTO TRIMESTRE | BC2: PRIMER TRIMESTRE | BD2: SEGUNDO TRIMESTRE | BE2: TERCER TRIMESTRE | BF2: CUARTO TRIMESTRE | BG2: PRIMER TRIMESTRE | BH2: SEGUNDO TRIMESTRE | BI2: TERCER TRIMESTRE | BJ2: CUARTO TRIMESTRE | BK2: PRIMER TRIMESTRE | BL2: SEGUNDO TRIMESTRE | BM2: TERCER TRIMESTRE | BN2: CUARTO TRIMESTRE | BO2: PRIMER TRIMESTRE | BP2: SEGUNDO TRIMESTRE | BQ2: TERCER TRIMESTRE | BR2: CUARTO TRIMESTRE | BS2: PRIMER TRIMESTRE | BT2: SEGUNDO TRIMESTRE | BU2: TERCER TRIMESTRE | BV2: CUARTO TRIMESTRE
A3: REGION 4 HEREDIA | B3: D-49 HEREDIA | D3: 291 | L3: 291 | T3: 291 | AE3: 544 | AJ3: 0 | BD3: 1 | BH3: 1 | BK3: 3 | BL3: 2 | BO3: 2 | BP3: 1 | BS3: 2 | BT3: 1
B4: D-50 BARVA | D4: 125 | L4: 113 | T4: 71 | AE4: 100 | AJ4: 0 | BD4: 1 | BH4: 1 | BL4: 0 | BO4: 2 | BP4: 1 | BT4: 1
B5: D-51 SANTO DOMINGO | D5: 125 | L5: 125 | T5: 125 | AE5: 124 | AJ5: 100 | BD5: 1 | BH5: 1 | BK5: 2 | BL5: 4 | BO5: 2 | BP5: 1
B6: D-52 SANTA BARBARA | D6: 332 | L6: 230 | T6: 260 | AE6: 128 | AJ6: 119 | BD6: 1 | BH6: 1 | BK6: 2 | BL6: 3 | BO6: 1 | BP6: 1 | BS6: 2
B7: D-53 SAN RAFAEL | D7: 125 | L7: 100 | T7: 60 | AE7: 160 | AJ7: 0 | BD7: 1 | BH7: 1 | BK7: 2 | BL7: 2 | BO7: 2 | BP7: 2
B8: D-54 SAN ISIDRO | D8: 206 | L8: 279 | T8: 254 | AE8: 560 | AJ8: 0 | BD8: 1 | BH8: 1 | BK8: 1 Justificación | BL8: 2 | BO8: 2 Justificación | BP8: 3
B9: D-55 BELEN | D9: 264 | L9: 266 | T9: 82 | AE9: 891 | AJ9: 0 | BD9: 1 | BH9: 1 | BK9: 2 | BL9: 2 | BO9: 1 | BP9: 2
B10: D-56 FLORES | D10: 125 | L10: 100 | T10: 50 | AE10: 156 | AJ10: 0 | BD10: 1 | BH10: 1 | BK10: 2 | BL10: 2 | BO10: 2 | BP10: 2
B11: D-57 SAN PABLO | D11: 125 | L11: 135 | T11: 132 | AE11: 1300 | AJ11: 0 | BD11: 1 | BH11: 1 | BK11: 2 | BL11: 3 | BO11: 2 | BP11: 3 | BS11: 1 | BT11: 2
C12: =SUM(C3:C11) -> 0 | D12: =SUM(D3:D11) -> 1718 | E12: =SUM(E3:E11) -> 0 | F12: =SUM(F3:F11) -> 0 | G12: =SUM(G3:G11) -> 0 | H12: =SUM(H3:H11) -> 0 | I12: =SUM(I3:I11) -> 0 | J12: =SUM(J3:J11) -> 0 | ... BC12: =SUM(BC3:BC11) -> 0 | BE12: =SUM(BE3:BE11) -> 0 | BF12: =SUM(BF3:BF11) -> 0 | BG12: =SUM(BG3:BG11) -> 0 | BI12: =SUM(BI3:BI11) -> 0 | BJ12: =SUM(BJ3:BJ11) -> 0 | BK12: =SUM(BK3:BK11) -> 15 | BL12: =SUM(BL3:BL11) -> 20 | BM12: =SUM(BM3:BM11) -> 0 | BN12: =SUM(BN3:BN11) -> 0 | BO12: =SUM(BO3:BO11) -> 14 | BP12: =SUM(BP3:BP11) -> 16 | ... BV12: =SUM(BV3:BV11) -> 0
B13: TOTAL | C13: =SUM(C12+D12+E12+F12) -> 1718 | G13: =SUM(G12+H12+I12+J12) -> 0 | K13: =SUM(K12+L12+M12+N12) -> 1639 | O13: =SUM(O12+P12+Q12+R12) -> 0 | S13: =SUM(S12+T12+U12+V12) -> 1325 | W13: =SUM(W12+X12+Y12+Z12) -> 0 | AA13: =SUM(AA12+AB12+AC12+AD12) -> 0 | AE13: =SUM(AE12:AH12) -> 3963 | AI13: =SUM(AI12+AJ12+AK12+AL12) -> 219 | AM13: =SUM(AM12+AN12+AO12+AP12) -> 0 | AQ13: =SUM(AQ12+AR12+AS12+AT12) -> 0 | AU13: =SUM(AU12:AX12) -> 0 | AY13: =SUM(AY12:BB12) -> 0 | BC13: =SUM(BC12:BF12) -> 0 | BG13: =SUM(BG12:BJ12) -> 0 | BK13: =SUM(BK12:BN12) -> 35 | BO13: =SUM(BO12:BR12) -> 30 | BS13: =SUM(BS12:BV12) -> 9

Sheet REGION 5 CHOROTEGA
A1: REGION | B1: DELEGACION POLICIAL | C1: ACTIVIDAD 1 CHARLA PREVENCIÓN DE LA VIOLENCIA EN RELACIONES DE PAREJA EJE 1 PLANOVI (JOVENES ADOLESCENTES) EJECUTAR MES DE MAYO LÍNEA BASE 125 PERSONAS | G1: ACTIVIDAD 2 CHARLA PREVENCIÓN DE LA VIOLENCIA DOMÉSTICA E INTRAFAMILIAR EJE 1 PLANOVI (PERSONAS ADULTAS) EJECUTAR MES DE AGOSTO LINEA BASE 25 PERSONAS | K1: ACTIVIDAD 3 CHARLA PREVENCIÓN DE LA MASCULINIDAD POR LA IGUALDAD EJE 2 PLANOVI (JOVENES Y ADOLESCENTES) EJECUTAR MES DE MAYO LÍNEA BASE 100 PERSONAS | O1: ACTIVIDAD 4 CHARLA PREVENCIÓN DE LA MASCULINIDAD POR LA IGUALDAD ADULTOS EJE 2 PLANOVI (COMUNIDAD) EJECUTAR MES DE AGOSTO LÍNEA BASE 15 PERSONAS | S1: ACTIVIDAD 5 CHARLA TRATA DE PERSONAS JOVENES ADOLESCENTES EJE 1 CONATT EJECUTAR MES DE MAYO LÍNEA BASE 50 PERSONAS | W1: ACTIVIDAD 6 CHARLA TRATA DE PERSONAS ADULTOS COMUNIDADES EJE 1 CONATT EJECUTAR MES DE AGOSTO LÍNEA BASE 10 PARTICIPANTES | AA1: ACTIVIDAD 7 CHARLA PREVENCIÓN DEL FEMICIDIO Y DIVULGACION COMITES CLAIS PERSONAS ADULTAS EJE 6 PLANOVI EJECUTAR MES DE OCTUBRE LÍNEA BASE 15 | AE1: ACTIVIDAD 8 ESTRATEGIA DE COMUNICACIÓN EJE 1 PLANOVI PREVENCION DE LA VIOLENCIA CONTRA LAS MUJERES EJECUTAR MES DE MARZO LÍNEA BASE 100 PERSONAS | AI1: ACTIVIDAD 9 ESTRATEGIA DE COMUNICACIÓN EJE 2 PLANOVI MASCULINIDAD POR LA IGUALDAD EJECUTAR MES DE JUNIO LÍNEA BASE 100 PERSONAS | AM1: ACTIVIDAD 10 ESTRATEGIA DE COMUNICACIÓN EJE 5 PLANOVI PREVENCIÓN, ATENCIÓN INTEGRAL Y NO-REVICTIMIZACIÓN FRENTE A LA VIOLENCIA SEXUAL EJECUTAR MES DE SETIEMBRE LÍNEA BASE 100 PERSONAS | AQ1: ACTIVIDAD 11 ESTRATEGIA DE COMUNICACIÓN EJE 6 PLANOVI PREVENCIÓN DEL FEMICIDIO EJECUTAR MES DE NOVIEMBRE LÍNEA BASE 100 PERSONAS | AU1: ACTIVIDAD 12 ESTRATEGIA DE COMUNICACIÓN EJE 1 CONATT CONTRA LA TRATA DE PERSONAS EJECUTAR MES DE JULIO LÍNEA BASE 100 PERSONAS | AY1: ACTIVIDAD 13 ESTRATEGIA DE COMUNICACIÓN EJE 1 CONATT TRAFICO ILICITO PERSONAS MIGRANTES EJECUTAR MES DE DICIEMBRE LÍNEA BASE 100 PERSONAS | BC1: ACTIVIDAD 14 ESTRATEGIA DE COMUNICACIÓN JUSTICIA RESTAURATIVA EJECUTAR MES DE ABRIL 50% COMITÉS SEGURIDAD COMUNITARIA | BG1: ACTIVIDAD 15 ESTRATEGIA DE COMUNICACIÓN JUSTICIA RESTAURATIVA EJECUTAR MES DE ABRIL 50% COMERCIOS | BK1: ACTIVIDAD 16 REPRESENTACION INSTITUCIONAL REDES CONTRA LA VIOLENCIA INTRAFAMILIAR PLANOVI CANTIDAD DE PARTICIPACIÓN POR TRIMESTRE | BO1: ACTIVIDAD 17 REPRESENTACION INSTITUCIONAL SUBSISTEMA LOCAL NIÑEZ Y ADOLESCENCIA (PANI) CANTIDAD DE PARTICIPACIÓN POR TRIMESTRE | BS1: ACTIVIDAD 18 REPRESENTACION INSTITUCIONAL COMITÉ LOCAL CLAIS (PODER JUDICIAL-INAMU-FUERZA PUBLICA) CANTIDAD DE PARTICIPACIÓN POR TRIMESTRE
C2: PRIMER TRIMESTRE | D2: SEGUNDO TRIMESTRE | E2: TERCER TRIMESTRE | F2: CUARTO TRIMESTRE | G2: PRIMER TRIMESTRE | H2: SEGUNDO TRIMESTRE | I2: TERCER TRIMESTRE | J2: CUARTO TRIMESTRE | K2: PRIMER TRIMESTRE | L2: SEGUNDO TRIMESTRE | M2: TERCER TRIMESTRE | N2: CUARTO TRIMESTRE | O2: PRIMER TRIMESTRE | P2: SEGUNDO TRIMESTRE | Q2: TERCER TRIMESTRE | R2: CUARTO TRIMESTRE | S2: PRIMER TRIMESTRE | T2: SEGUNDO TRIMESTRE | U2: TERCER TRIMESTRE | V2: CUARTO TRIMESTRE | W2: PRIMER TRIMESTRE | X2: SEGUNDO TRIMESTRE | Y2: TERCER TRIMESTRE | Z2: CUARTO TRIMESTRE | AA2: PRIMER TRIMESTRE | AB2: SEGUNDO TRIMESTRE | AC2: TERCER TRIMESTRE | AD2: CUARTO TRIMESTRE | AE2: PRIMER TRIMESTRE | AF2: SEGUNDO TRIMESTRE | AG2: TERCER TRIMESTRE | AH2: CUARTO TRIMESTRE | AI2: PRIMER TRIMESTRE | AJ2: SEGUNDO TRIMESTRE | AK2: TERCER TRIMESTRE | AL2: CUARTO TRIMESTRE | AM2: PRIMER TRIMESTRE | AN2: SEGUNDO TRIMESTRE | AO2: TERCER TRIMESTRE | AP2: CUARTO TRIMESTRE | AQ2: PRIMER TRIMESTRE | AR2: SEGUNDO TRIMESTRE | AS2: TERCER TRIMESTRE | AT2: CUARTO TRIMESTRE | AU2: PRIMER TRIMESTRE | AV2: SEGUNDO TRIMESTRE | AW2: TERCER TRIMESTRE | AX2: CUARTO TRIMESTRE | AY2: PRIMER TRIMESTRE | AZ2: SEGUNDO TRIMESTRE | BA2: TERCER TRIMESTRE | BB2: CUARTO TRIMESTRE | BC2: PRIMER TRIMESTRE | BD2: SEGUNDO TRIMESTRE | BE2: TERCER TRIMESTRE | BF2: CUARTO TRIMESTRE | BG2: PRIMER TRIMESTRE | BH2: SEGUNDO TRIMESTRE | BI2: TERCER TRIMESTRE | BJ2: CUARTO TRIMESTRE | BK2: PRIMER TRIMESTRE | BL2: SEGUNDO TRIMESTRE | BM2: TERCER TRIMESTRE | BN2: CUARTO TRIMESTRE | BO2: PRIMER TRIMESTRE | BP2: SEGUNDO TRIMESTRE | BQ2: TERCER TRIMESTRE | BR2: CUARTO TRIMESTRE | BS2: PRIMER TRIMESTRE | BT2: SEGUNDO TRIMESTRE | BU2: TERCER TRIMESTRE | BV2: CUARTO TRIMESTRE
A3: REGION 5 CHOROTEGA | B3: D-60 LIBERIA | D3: 150 | L3: 100 | T3: 80 | AE3: 1560 | AJ3: 0 | BD3: 1 | BH3: 1 | BK3: 3 | BL3: 3 | BO3: 2 | BP3: 1 | BT3: 1
B4: D-61 NICOYA | D4: 125 | L4: 100 | T4: 50 | AE4: 995 | AJ4: 886 | BD4: 1 | BH4: 1 | BK4: 2 | BL4: 3 | BO4: 2 | BP4: 2 | BT4: 2
B5: D-62 SANTA CRUZ | D5: 125 | L5: 100 | T5: 50 | AE5: 476 | AJ5: 301 | BD5: 1 | BH5: 1 | BK5: 1 | BL5: 3 | BP5: 0 | BS5: 1 | BT5: 3
B6: D-63 BAGACES | D6: 125 | L6: 100 | T6: 50 | AE6: 190 | AJ6: 0 | BD6: 1 | BH6: 1 | BK6: 2 | BL6: 2 | BO6: 2 | BP6: 2
B7: D-64 CARRILLO | D7: 127 | L7: 105 | T7: 60 | AE7: 115 | AJ7: 0 | BD7: 1 | BH7: 1 | BL7: 1 | BP7: 0
B8: D-65 CAÑAS | D8: 124 | L8: 123 | T8: 104 | AE8: 500 | AJ8: 0 | BD8: 1 | BH8: 1 | BK8: 1 | BL8: 3 | BO8: 1 | BP8: 3 | BS8: 2 | BT8: 3
B9: D-66 ABANGARES | D9: 125 | L9: 136 | T9: 50 | AE9: 354 | AJ9: 0 | BD9: 1 | BH9: 1 | BK9: 2 | BL9: 2 | BO9: 2 | BP9: 3
B10: D-67 TILARAN | D10: 125 | L10: 100 | T10: 50 | AE10: 105 | AJ10: 100 | BD10: 1 | BH10: 1 | BK10: 1 | BL10: 2 | BP10: 0
B11: D-68 NANDAYURE | D11: 173 | L11: 189 | T11: 64 | AE11: 105 | AJ11: 0 | BD11: 1 | BH11: 1 | BK11: 1 | BL11: 3 | BO11: 1 | BP11: 3
B12: D-69 HOJANCHA | D12: 125 | L12: 100 | T12: 50 | AE12: 100 | AJ12: 0 | BD12: 1 | BH12: 1 | BK12: 1 | BL12: 2 | BO12: 1 | BP12: 3
B13: D-70 LA CRUZ | D13: 129 | L13: 100 | T13: 95 | AE13: 504 | AJ13: 0 | BD13: 1 | BH13: 1 | BK13: 1 | BL13: 2 | BO13: 1 | BP13: 2 | BS13: 1 | BT13: 2
C14: =SUM(C3:C13) -> 0 | D14: =SUM(D3:D13) -> 1453 | E14: =SUM(E3:E13) -> 0 | F14: =SUM(F3:F13) -> 0 | G14: =SUM(G3:G13) -> 0 | H14: =SUM(H3:H13) -> 0 | I14: =SUM(I3:I13) -> 0 | J14: =SUM(J3:J13) -> 0 | ... BC14: =SUM(BC3:BC13) -> 0 | BD14: 1 | BE14: =SUM(BE3:BE13) -> 0 | BF14: =SUM(BF3:BF13) -> 0 | BG14: =SUM(BG3:BG13) -> 0 | BH14: 1 | BI14: =SUM(BI3:BI13) -> 0 | BJ14: =SUM(BJ3:BJ13) -> 0 | BK14: =SUM(BK3:BK13) -> 15 | BL14: =SUM(BL3:BL13) -> 26 | BM14: =SUM(BM3:BM13) -> 0 | BN14: =SUM(BN3:BN13) -> 0 | BO14: =SUM(BO3:BO13) -> 12 | BP14: =SUM(BP3:BP13) -> 19 | ... BV14: =SUM(BV3:BV13) -> 0
B15: TOTAL | C15: =SUM(C14+D14+E14+F14) -> 1453 | G15: =SUM(G14+H14+I14+J14) -> 0 | K15: =SUM(K14+L14+M14+N14) -> 1253 | O15: =SUM(O14+P14+Q14+R14) -> 0 | S15: =SUM(S14+T14+U14+V14) -> 703 | W15: =SUM(W14+X14+Y14+Z14) -> 0 | AA15: =SUM(AA14+AB14+AC14+AD14) -> 0 | AE15: =SUM(AE14:AH14) -> 5004 | AI15: =SUM(AI14+AJ14+AK14+AL14) -> 1287 | AM15: =SUM(AM14+AN14+AO14+AP14) -> 0 | AQ15: =SUM(AQ14+AR14+AS14+AT14) -> 0 | AU15: =SUM(AU14:AX14) -> 0 | AY15: =SUM(AY14:BB14) -> 0 | BC15: 1 | BG15: 1 | BK15: =SUM(BK14:BN14) -> 41 | BO15: =SUM(BO14:BR14) -> 31 | BS15: =SUM(BS14:BV14) -> 15

Sheet REGION 6 PAC CENTRAL
A1: REGION | B1: DELEGACION POLICIAL | C1: ACTIVIDAD 1 CHARLA PREVENCIÓN DE LA VIOLENCIA EN RELACIONES DE PAREJA EJE 1 PLANOVI (JOVENES ADOLESCENTES) EJECUTAR MES DE MAYO LÍNEA BASE 100 PERSONAS | G1: ACTIVIDAD 2 CHARLA PREVENCIÓN DE LA VIOLENCIA DOMÉSTICA E INTRAFAMILIAR EJE 1 PLANOVI (PERSONAS ADULTAS) EJECUTAR MES DE AGOSTO LINEA BASE 25 PERSONAS | K1: ACTIVIDAD 3 CHARLA PREVENCIÓN DE LA MASCULINIDAD POR LA IGUALDAD EJE 2 PLANOVI (JOVENES Y ADOLESCENTES) EJECUTAR MES DE MAYO LÍNEA BASE 75 PERSONAS | O1: ACTIVIDAD 4 CHARLA PREVENCIÓN DE LA MASCULINIDAD POR LA IGUALDAD ADULTOS EJE 2 PLANOVI (COMUNIDAD) EJECUTAR MES DE AGOSTO LÍNEA BASE 15 PERSONAS | S1: ACTIVIDAD 5 CHARLA TRATA DE PERSONAS JOVENES ADOLESCENTES EJE 1 CONATT EJECUTAR MES DE MAYO LÍNEA BASE 50 PERSONAS | W1: ACTIVIDAD 6 CHARLA TRATA DE PERSONAS ADULTOS COMUNIDADES EJE 1 CONATT EJECUTAR MES DE AGOSTO LÍNEA BASE 10 PARTICIPANTES | AA1: ACTIVIDAD 7 CHARLA PREVENCIÓN DEL FEMICIDIO Y DIVULGACION COMITES CLAIS PERSONAS ADULTAS EJE 6 PLANOVI EJECUTAR MES DE OCTUBRE LÍNEA BASE 15 | AE1: ACTIVIDAD 8 ESTRATEGIA DE COMUNICACIÓN EJE 1 PLANOVI PREVENCION DE LA VIOLENCIA CONTRA LAS MUJERES EJECUTAR MES DE MARZO LÍNEA BASE 100 PERSONAS | AI1: ACTIVIDAD 9 ESTRATEGIA DE COMUNICACIÓN EJE 2 PLANOVI MASCULINIDAD POR LA IGUALDAD EJECUTAR MES DE JUNIO LÍNEA BASE 100 PERSONAS | AM1: ACTIVIDAD 10 ESTRATEGIA DE COMUNICACIÓN EJE 5 PLANOVI PREVENCIÓN, ATENCIÓN INTEGRAL Y NO-REVICTIMIZACIÓN FRENTE A LA VIOLENCIA SEXUAL EJECUTAR MES DE SETIEMBRE LÍNEA BASE 100 PERSONAS | AQ1: ACTIVIDAD 11 ESTRATEGIA DE COMUNICACIÓN EJE 6 PLANOVI PREVENCIÓN DEL FEMICIDIO EJECUTAR MES DE NOVIEMBRE LÍNEA BASE 100 PERSONAS | AU1: ACTIVIDAD 12 ESTRATEGIA DE COMUNICACIÓN EJE 1 CONATT CONTRA LA TRATA DE PERSONAS EJECUTAR MES DE JULIO LÍNEA BASE 100 PERSONAS | AY1: ACTIVIDAD 13 ESTRATEGIA DE COMUNICACIÓN EJE 1 CONATT TRAFICO ILICITO PERSONAS MIGRANTES EJECUTAR MES DE DICIEMBRE LÍNEA BASE 100 PERSONAS | BC1: ACTIVIDAD 14 ESTRATEGIA DE COMUNICACIÓN JUSTICIA RESTAURATIVA EJECUTAR MES DE ABRIL 50% COMITÉS SEGURIDAD COMUNITARIA | BG1: ACTIVIDAD 15 ESTRATEGIA DE COMUNICACIÓN JUSTICIA RESTAURATIVA EJECUTAR MES DE ABRIL 50% COMERCIOS | BK1: ACTIVIDAD 16 REPRESENTACION INSTITUCIONAL REDES CONTRA LA VIOLENCIA INTRAFAMILIAR PLANOVI CANTIDAD DE PARTICIPACIÓN POR TRIMESTRE | BO1: ACTIVIDAD 17 REPRESENTACION INSTITUCIONAL SUBSISTEMA LOCAL NIÑEZ Y ADOLESCENCIA (PANI) CANTIDAD DE PARTICIPACIÓN POR TRIMESTRE | BS1: ACTIVIDAD 18 REPRESENTACION INSTITUCIONAL COMITÉ LOCAL CLAIS (PODER JUDICIAL-INAMU-FUERZA PUBLICA) CANTIDAD DE PARTICIPACIÓN POR TRIMESTRE
C2: PRIMER TRIMESTRE | D2: SEGUNDO TRIMESTRE | E2: TERCER TRIMESTRE | F2: CUARTO TRIMESTRE | G2: PRIMER TRIMESTRE | H2: SEGUNDO TRIMESTRE | I2: TERCER TRIMESTRE | J2: CUARTO TRIMESTRE | K2: PRIMER TRIMESTRE | L2: SEGUNDO TRIMESTRE | M2: TERCER TRIMESTRE | N2: CUARTO TRIMESTRE | O2: PRIMER TRIMESTRE | P2: SEGUNDO TRIMESTRE | Q2: TERCER TRIMESTRE | R2: CUARTO TRIMESTRE | S2: PRIMER TRIMESTRE | T2: SEGUNDO TRIMESTRE | U2: TERCER TRIMESTRE | V2: CUARTO TRIMESTRE | W2: PRIMER TRIMESTRE | X2: SEGUNDO TRIMESTRE | Y2: TERCER TRIMESTRE | Z2: CUARTO TRIMESTRE | AA2: PRIMER TRIMESTRE | AB2: SEGUNDO TRIMESTRE | AC2: TERCER TRIMESTRE | AD2: CUARTO TRIMESTRE | AE2: PRIMER TRIMESTRE | AF2: SEGUNDO TRIMESTRE | AG2: TERCER TRIMESTRE | AH2: CUARTO TRIMESTRE | AI2: PRIMER TRIMESTRE | AJ2: SEGUNDO TRIMESTRE | AK2: TERCER TRIMESTRE | AL2: CUARTO TRIMESTRE | AM2: PRIMER TRIMESTRE | AN2: SEGUNDO TRIMESTRE | AO2: TERCER TRIMESTRE | AP2: CUARTO TRIMESTRE | AQ2: PRIMER TRIMESTRE | AR2: SEGUNDO TRIMESTRE | AS2: TERCER TRIMESTRE | AT2: CUARTO TRIMESTRE | AU2: PRIMER TRIMESTRE | AV2: SEGUNDO TRIMESTRE | AW2: TERCER TRIMESTRE | AX2: CUARTO TRIMESTRE | AY2: PRIMER TRIMESTRE | AZ2: SEGUNDO TRIMESTRE | BA2: TERCER TRIMESTRE | BB2: CUARTO TRIMESTRE | BC2: PRIMER TRIMESTRE | BD2: SEGUNDO TRIMESTRE | BE2: TERCER TRIMESTRE | BF2: CUARTO TRIMESTRE | BG2: PRIMER TRIMESTRE | BH2: SEGUNDO TRIMESTRE | BI2: TERCER TRIMESTRE | BJ2: CUARTO TRIMESTRE | BK2: PRIMER TRIMESTRE | BL2: SEGUNDO TRIMESTRE | BM2: TERCER TRIMESTRE | BN2: CUARTO TRIMESTRE | BO2: PRIMER TRIMESTRE | BP2: SEGUNDO TRIMESTRE | BQ2: TERCER TRIMESTRE | BR2: CUARTO TRIMESTRE | BS2: PRIMER TRIMESTRE | BT2: SEGUNDO TRIMESTRE | BU2: TERCER TRIMESTRE | BV2: CUARTO TRIMESTRE
A3: REION 6 PACIFICO CENTRAL | B3: D-71 PUNTARENAS | D3: 185 | L3: 158 | T3: 78 | AE3: 301 | AJ3: 0 | BD3: 1 | BH3: 1 | BK3: 1 | BL3: 0 | BO3: 2 | BP3: 0 | BS3: 1 | BT3: 1
B4: D-72 ESPARZA | D4: 131 | L4: 100 | T4: 50 | AE4: 119 | AJ4: 0 | BD4: 1 | BH4: 1 | BK4: 2 | BL4: 2 | BO4: 2 | BP4: 2
B5: D-73 MONTES DE ORO | D5: 125 | L5: 103 | T5: 53 | AE5: 100 | AJ5: 301 | BD5: 1 | BH5: 1 | BK5: 2 | BL5: 0 | BO5: 2 | BP5: 0
B6: D-74 QUEPOS | D6: 170 | L6: 128 | T6: 166 | AE6: 100 | AJ6: 0 | BD6: 1 | BH6: 1 | BK6: 1 | BL6: 2 | BP6: 2 | BS6: 1 | BT6: 1
B7: D-75 PARRITA | D7: 150 | L7: 100 | T7: 60 | AE7: 100 | AJ7: 0 | BD7: 1 | BH7: 1 | BL7: 1 | BO7: 1 | BP7: 1 | BS7: 1 | BT7: 1
B8: D-76 GARABITO | D8: 243 | L8: 141 | T8: 108 | AE8: 135 | AJ8: 0 | BD8: 1 | BH8: 1 | BK8: 1 | BL8: 1 | BO8: 1 | BP8: 1 | BS8: 1 | BT8: 1
B9: D-77 PAQUERA | D9: 136 | L9: Justificacion | T9: 68 | AE9: 157 | AJ9: 0 | BD9: 1 | BH9: 1 | BK9: 1 | BL9: 1 | BO9: 2 | BP9: 1
B10: D-78 JUDAS DE CHOMES | D10: 140 | L10: 140 | T10: 140 | AE10: 226 | AJ10: 0 | BD10: 1 | BH10: 1 | BL10: 0 | BP10: 0
C11: =SUM(C3:C10) -> 0 | D11: =SUM(D3:D10) -> 1280 | E11: =SUM(E3:E10) -> 0 | F11: =SUM(F3:F10) -> 0 | G11: =SUM(G3:G10) -> 0 | H11: =SUM(H3:H10) -> 0 | I11: =SUM(I3:I10) -> 0 | J11: =SUM(J3:J10) -> 0 | ... BB11: =SUM(BB3:BB10) -> 0 | BK11: =SUM(BK3:BK10) -> 8 | BL11: =SUM(BL3:BL10) -> 7 | BM11: =SUM(BM3:BM10) -> 0 | BN11: =SUM(BN3:BN10) -> 0 | BO11: =SUM(BO3:BO10) -> 10 | BP11: =SUM(BP3:BP10) -> 7 | BQ11: =SUM(BQ3:BQ10) -> 0 | BR11: =SUM(BR3:BR10) -> 0 | ... BV11: =SUM(BV3:BV10) -> 0
B12: TOTAL | C12: =SUM(C11+D11+E11+F11) -> 1280 | G12: =SUM(G11+H11+I11+J11) -> 0 | K12: =SUM(K11+L11+M11+N11) -> 870 | O12: =SUM(O11+P11+Q11+R11) -> 0 | S12: =SUM(S11+T11+U11+V11) -> 723 | W12: =SUM(W11+X11+Y11+Z11) -> 0 | AA12: =SUM(AA11+AB11+AC11+AD11) -> 0 | AE12: =SUM(AE11:AH11) -> 1238 | AI12: =SUM(AI11+AJ11+AK11+AL11) -> 301 | AM12: =SUM(AM11+AN11+AO11+AP11) -> 0 | AQ12: =SUM(AQ11+AR11+AS11+AT11) -> 0 | AU12: =SUM(AU11:AX11) -> 0 | AY12: =SUM(AY11:BB11) -> 0 | BC12: 1 | BG12: 1 | BK12: =SUM(BK11:BN11) -> 15 | BO12: =SUM(BO11:BR11) -> 17 | BS12: =SUM(BS11:BV11) -> 8

Sheet REGION 7 BRUNCA
A1: REGION | B1: DELEGACION POLICIAL | C1: ACTIVIDAD 1 CHARLA PREVENCIÓN DE LA VIOLENCIA EN RELACIONES DE PAREJA EJE 1 PLANOVI (JOVENES ADOLESCENTES) EJECUTAR MES DE MAYO LÍNEA BASE 100 PERSONAS | G1: ACTIVIDAD 2 CHARLA PREVENCIÓN DE LA VIOLENCIA DOMÉSTICA E INTRAFAMILIAR EJE 1 PLANOVI (PERSONAS ADULTAS) EJECUTAR MES DE AGOSTO LINEA BASE 25 PERSONAS | K1: ACTIVIDAD 3 CHARLA PREVENCIÓN DE LA MASCULINIDAD POR LA IGUALDAD EJE 2 PLANOVI (JOVENES Y ADOLESCENTES) EJECUTAR MES DE MAYO LÍNEA BASE 75 PERSONAS | O1: ACTIVIDAD 4 CHARLA PREVENCIÓN DE LA MASCULINIDAD POR LA IGUALDAD ADULTOS EJE 2 PLANOVI (COMUNIDAD) EJECUTAR MES DE AGOSTO LÍNEA BASE 15 PERSONAS | S1: ACTIVIDAD 5 CHARLA TRATA DE PERSONAS JOVENES ADOLESCENTES EJE 1 CONATT EJECUTAR MES DE MAYO LÍNEA BASE 50 PERSONAS | W1: ACTIVIDAD 6 CHARLA TRATA DE PERSONAS ADULTOS COMUNIDADES EJE 1 CONATT EJECUTAR MES DE AGOSTO LÍNEA BASE 10 PARTICIPANTES | AA1: ACTIVIDAD 7 CHARLA PREVENCIÓN DEL FEMICIDIO Y DIVULGACION COMITES CLAIS PERSONAS ADULTAS EJE 6 PLANOVI EJECUTAR MES DE OCTUBRE LÍNEA BASE 15 | AE1: ACTIVIDAD 8 ESTRATEGIA DE COMUNICACIÓN EJE 1 PLANOVI PREVENCION DE LA VIOLENCIA CONTRA LAS MUJERES EJECUTAR MES DE MARZO LÍNEA BASE 100 PERSONAS | AI1: ACTIVIDAD 9 ESTRATEGIA DE COMUNICACIÓN EJE 2 PLANOVI MASCULINIDAD POR LA IGUALDAD EJECUTAR MES DE JUNIO LÍNEA BASE 100 PERSONAS | AM1: ACTIVIDAD 10 ESTRATEGIA DE COMUNICACIÓN EJE 5 PLANOVI PREVENCIÓN, ATENCIÓN INTEGRAL Y NO-REVICTIMIZACIÓN FRENTE A LA VIOLENCIA SEXUAL EJECUTAR MES DE SETIEMBRE LÍNEA BASE 100 PERSONAS | AQ1: ACTIVIDAD 11 ESTRATEGIA DE COMUNICACIÓN EJE 6 PLANOVI PREVENCIÓN DEL FEMICIDIO EJECUTAR MES DE NOVIEMBRE LÍNEA BASE 100 PERSONAS | AU1: ACTIVIDAD 12 ESTRATEGIA DE COMUNICACIÓN EJE 1 CONATT CONTRA LA TRATA DE PERSONAS EJECUTAR MES DE JULIO LÍNEA BASE 100 PERSONAS | AY1: ACTIVIDAD 13 ESTRATEGIA DE COMUNICACIÓN EJE 1 CONATT TRAFICO ILICITO PERSONAS MIGRANTES EJECUTAR MES DE DICIEMBRE LÍNEA BASE 100 PERSONAS | BC1: ACTIVIDAD 14 ESTRATEGIA DE COMUNICACIÓN JUSTICIA RESTAURATIVA EJECUTAR MES DE ABRIL 50% COMITÉS SEGURIDAD COMUNITARIA | BG1: ACTIVIDAD 15 ESTRATEGIA DE COMUNICACIÓN JUSTICIA RESTAURATIVA EJECUTAR MES DE ABRIL 50% COMERCIOS | BK1: ACTIVIDAD 16 REPRESENTACION INSTITUCIONAL REDES CONTRA LA VIOLENCIA INTRAFAMILIAR PLANOVI CANTIDAD DE PARTICIPACIÓN POR TRIMESTRE | BO1: ACTIVIDAD 17 REPRESENTACION INSTITUCIONAL SUBSISTEMA LOCAL NIÑEZ Y ADOLESCENCIA (PANI) CANTIDAD DE PARTICIPACIÓN POR TRIMESTRE | BS1: ACTIVIDAD 18 REPRESENTACION INSTITUCIONAL COMITÉ LOCAL CLAIS (PODER JUDICIAL-INAMU-FUERZA PUBLICA) CANTIDAD DE PARTICIPACIÓN POR TRIMESTRE
C2: PRIMER TRIMESTRE | D2: SEGUNDO TRIMESTRE | E2: TERCER TRIMESTRE | F2: CUARTO TRIMESTRE | G2: PRIMER TRIMESTRE | H2: SEGUNDO TRIMESTRE | I2: TERCER TRIMESTRE | J2: CUARTO TRIMESTRE | K2: PRIMER TRIMESTRE | L2: SEGUNDO TRIMESTRE | M2: TERCER TRIMESTRE | N2: CUARTO TRIMESTRE | O2: PRIMER TRIMESTRE | P2: SEGUNDO TRIMESTRE | Q2: TERCER TRIMESTRE | R2: CUARTO TRIMESTRE | S2: PRIMER TRIMESTRE | T2: SEGUNDO TRIMESTRE | U2: TERCER TRIMESTRE | V2: CUARTO TRIMESTRE | W2: PRIMER TRIMESTRE | X2: SEGUNDO TRIMESTRE | Y2: TERCER TRIMESTRE | Z2: CUARTO TRIMESTRE | AA2: PRIMER TRIMESTRE | AB2: SEGUNDO TRIMESTRE | AC2: TERCER TRIMESTRE | AD2: CUARTO TRIMESTRE | AE2: PRIMER TRIMESTRE | AF2: SEGUNDO TRIMESTRE | AG2: TERCER TRIMESTRE | AH2: CUARTO TRIMESTRE | AI2: PRIMER TRIMESTRE | AJ2: SEGUNDO TRIMESTRE | AK2: TERCER TRIMESTRE | AL2: CUARTO TRIMESTRE | AM2: PRIMER TRIMESTRE | AN2: SEGUNDO TRIMESTRE | AO2: TERCER TRIMESTRE | AP2: CUARTO TRIMESTRE | AQ2: PRIMER TRIMESTRE | AR2: SEGUNDO TRIMESTRE | AS2: TERCER TRIMESTRE | AT2: CUARTO TRIMESTRE | AU2: PRIMER TRIMESTRE | AV2: SEGUNDO TRIMESTRE | AW2: TERCER TRIMESTRE | AX2: CUARTO TRIMESTRE | AY2: PRIMER TRIMESTRE | AZ2: SEGUNDO TRIMESTRE | BA2: TERCER TRIMESTRE | BB2: CUARTO TRIMESTRE | BC2: PRIMER TRIMESTRE | BD2: SEGUNDO TRIMESTRE | BE2: TERCER TRIMESTRE | BF2: CUARTO TRIMESTRE | BG2: PRIMER TRIMESTRE | BH2: SEGUNDO TRIMESTRE | BI2: TERCER TRIMESTRE | BJ2: CUARTO TRIMESTRE | BK2: PRIMER TRIMESTRE | BL2: SEGUNDO TRIMESTRE | BM2: TERCER TRIMESTRE | BN2: CUARTO TRIMESTRE | BO2: PRIMER TRIMESTRE | BP2: SEGUNDO TRIMESTRE | BQ2: TERCER TRIMESTRE | BR2: CUARTO TRIMESTRE | BS2: PRIMER TRIMESTRE | BT2: SEGUNDO TRIMESTRE | BU2: TERCER TRIMESTRE | BV2: CUARTO TRIMESTRE
A3: REGION 7 BRUNCA | B3: D-79 PEREZ ZELEDON | D3: 150 | L3: 109 | T3: 67 | AE3: 150 | AJ3: 0 | BD3: 1 | BH3: 1 | BK3: 5 | BL3: 2 | BO3: 1 | BP3: 2 | BS3: 1 | BT3: 2
B4: D-80 BUENOS AIRES | D4: 185 | L4: 100 | T4: 100 | AE4: 110 | AJ4: 0 | BD4: 1 | BH4: 1 | BK4: 3 | BL4: 1 | BO4: 2 | BP4: 2
B5: D-81 OSA | D5: 180 | L5: 110 | T5: 51 | AE5: 148 | AJ5: 0 | BD5: 1 | BH5: 1 | BK5: 2 | BL5: 2 | BO5: 3 | BP5: 2
C6: =SUM(C3:C5) -> 0 | D6: =SUM(D3:D5) -> 515 | E6: =SUM(E3:E5) -> 0 | F6: =SUM(F3:F5) -> 0 | G6: =SUM(G3:G5) -> 0 | H6: =SUM(H3:H5) -> 0 | I6: =SUM(I3:I5) -> 0 | J6: =SUM(J3:J5) -> 0 | ... BB6: =SUM(BB3:BB5) -> 0 | BK6: =SUM(BK3:BK5) -> 10 | BL6: =SUM(BL3:BL5) -> 5 | BM6: =SUM(BM3:BM5) -> 0 | BN6: =SUM(BN3:BN5) -> 0 | BO6: =SUM(BO3:BO5) -> 6 | BP6: =SUM(BP3:BP5) -> 6 | BQ6: =SUM(BQ3:BQ5) -> 0 | BR6: =SUM(BR3:BR5) -> 0 | ... BV6: =SUM(BV3:BV5) -> 0
B7: TOTAL | C7: =SUM(C6+D6+E6+F6) -> 515 | G7: =SUM(G6+H6+I6+J6) -> 0 | K7: =SUM(K6+L6+M6+N6) -> 319 | O7: =SUM(O6+P6+Q6+R6) -> 0 | S7: =SUM(S6+T6+U6+V6) -> 218 | W7: =SUM(W6+X6+Y6+Z6) -> 0 | AA7: =SUM(AA6+AB6+AC6+AD6) -> 0 | AE7: =SUM(AE6:AH6) -> 408 | AI7: =SUM(AI6+AJ6+AK6+AL6) -> 0 | AM7: =SUM(AM6+AN6+AO6+AP6) -> 0 | AQ7: =SUM(AQ6+AR6+AS6+AT6) -> 0 | AU7: =SUM(AU6:AX6) -> 0 | AY7: =SUM(AY6:BB6) -> 0 | BC7: 1 | BG7: 1 | BK7: =SUM(BK6:BN6) -> 15 | BO7: =SUM(BO6:BR6) -> 12 | BS7: =SUM(BS6:BV6) -> 3

Sheet REGION 8 HUETAR NORTE
